<robot name="g1">

  <mujoco>
    <compiler meshdir="meshes" discardvisual="false"/>
  </mujoco>



  <link name="pelvis">
    <inertial>
      <origin xyz="0 0 -0.07605" rpy="0 0 0"/>
      <mass value="2.86"/>
      <inertia ixx="0.0079143" ixy="0" ixz="1.6E-06" iyy="0.0069837" iyz="0" izz="0.0059404"/>
    </inertial>
    <visual>
      <origin xyz="0 0 0" rpy="0 0 0"/>
      <geometry>
        <mesh filename="package://gz_sim/meshes/g1/pelvis.STL"/>
      </geometry>
      <material name="white">
        <color rgba="0.7 0.7 0.7 1"/>
      </material>
    </visual>
    <collision>
      <origin xyz="0 0 0" rpy="0 0 0"/>
      <geometry>
        <mesh filename="package://gz_sim/meshes/g1/pelvis.STL"/>
      </geometry>
    </collision>
  </link>
  <link name="pelvis_contour_link">
    <visual>
      <origin xyz="0 0 0" rpy="0 0 0"/>
      <geometry>
        <mesh filename="package://gz_sim/meshes/g1/pelvis_contour_link.STL"/>
      </geometry>
      <material name="dark">
        <color rgba="0.2 0.2 0.2 1"/>
      </material>
    </visual>
  </link>
  <joint name="pelvis_contour_joint" type="fixed">
    <parent link="pelvis"/>
    <child link="pelvis_contour_link"/>
  <dynamics damping="0.0" friction="0.01"/></joint>

  <!-- Leg -->
  <link name="left_hip_pitch_link">
    <inertial>
      <origin xyz="0.001962 0.049392 -0.000941" rpy="0 0 0"/>
      <mass value="1.299"/>
      <inertia ixx="0.0013873" ixy="-1.63E-05" ixz="-1E-06" iyy="0.0009059" iyz="-4.24E-05" izz="0.0009196"/>
    </inertial>
    <visual>
      <origin xyz="0 0 0" rpy="0 0 0"/>
      <geometry>
        <mesh filename="package://gz_sim/meshes/g1/left_hip_pitch_link.STL"/>
      </geometry>
      <material name="dark">
        <color rgba="0.2 0.2 0.2 1"/>
      </material>
    </visual>
    <collision>
      <origin xyz="0 0 0" rpy="0 0 0"/>
      <geometry>
        <mesh filename="package://gz_sim/meshes/g1/left_hip_pitch_link.STL"/>
      </geometry>
    </collision>
  </link>
  <joint name="left_hip_pitch_joint" type="revolute">
    <origin xyz="0 0.06445 -0.1027" rpy="0 -0.34907 0"/>
    <parent link="pelvis"/>
    <child link="left_hip_pitch_link"/>
    <axis xyz="0 1 0"/>
    <limit lower="-2.35" upper="3.05" effort="88" velocity="32"/>

  <dynamics damping="0.0" friction="0.01"/></joint>
  <link name="left_hip_roll_link">
    <inertial>
      <origin xyz="0.024757 -0.001036 -0.086323" rpy="0 0 0"/>
      <mass value="1.446"/>
      <inertia ixx="0.0022702" ixy="-3.7E-06" ixz="-0.0003789" iyy="0.002304" iyz="-1.8E-05" izz="0.0016001"/>
    </inertial>
    <visual>
      <origin xyz="0 0 0" rpy="0 0 0"/>
      <geometry>
        <mesh filename="package://gz_sim/meshes/g1/left_hip_roll_link.STL"/>
      </geometry>
      <material name="white">
        <color rgba="0.7 0.7 0.7 1"/>
      </material>
    </visual>
    <collision>
      <origin xyz="0 0 0" rpy="0 0 0"/>
      <geometry>
        <mesh filename="package://gz_sim/meshes/g1/left_hip_roll_link.STL"/>
      </geometry>
    </collision>
  </link>
  <joint name="left_hip_roll_joint" type="revolute">
    <origin xyz="0 0.0523 0" rpy="0 0 0"/>
    <parent link="left_hip_pitch_link"/>
    <child link="left_hip_roll_link"/>
    <axis xyz="1 0 0"/>
    <limit lower="-0.26" upper="2.53" effort="88" velocity="32"/>
  <dynamics damping="0.0" friction="0.01"/><dynamics damping="0.0" friction="0.01"/></joint>
  <link name="left_hip_yaw_link">
    <inertial>
      <origin xyz="-0.053554 -0.011477 -0.14067" rpy="0 0 0"/>
      <mass value="2.052"/>
      <inertia ixx="0.0087264" ixy="-0.0004402" ixz="-0.0036676" iyy="0.011374" iyz="-0.0006654" izz="0.004279"/>
    </inertial>
    <visual>
      <origin xyz="0 0 0" rpy="0 0 0"/>
      <geometry>
        <mesh filename="package://gz_sim/meshes/g1/left_hip_yaw_link.STL"/>
      </geometry>
      <material name="white">
        <color rgba="0.7 0.7 0.7 1"/>
      </material>
    </visual>
    <collision>
      <origin xyz="0 0 0" rpy="0 0 0"/>
      <geometry>
        <mesh filename="package://gz_sim/meshes/g1/left_hip_yaw_link.STL"/>
      </geometry>
    </collision>
  </link>
  <joint name="left_hip_yaw_joint" type="revolute">
    <origin xyz="0.01966 -0.0012139 -0.1241" rpy="0 0 0"/>
    <parent link="left_hip_roll_link"/>
    <child link="left_hip_yaw_link"/>
    <axis xyz="0 0 1"/>
    <limit lower="-2.75" upper="2.75" effort="88" velocity="32"/>
  <dynamics damping="0.0" friction="0.01"/><dynamics damping="0.0" friction="0.01"/></joint>
  <link name="left_knee_link">
    <inertial>
      <origin xyz="0.005505 0.006534 -0.116629" rpy="0 0 0"/>
      <mass value="2.252"/>
      <inertia ixx="0.012443837" ixy="0.000053496" ixz="-0.000437641" iyy="0.012674902" iyz="-0.000682499" izz="0.001986501"/>
    </inertial>
    <visual>
      <origin xyz="0 0 0" rpy="0 0 0"/>
      <geometry>
        <mesh filename="package://gz_sim/meshes/g1/left_knee_link.STL"/>
      </geometry>
      <material name="white">
        <color rgba="0.7 0.7 0.7 1"/>
      </material>
    </visual>
    <collision>
      <origin xyz="0.007 0.005 -0.15" rpy="0 0 0"/>
      <geometry>
        <cylinder radius="0.015" length="0.15"/>
      </geometry>
    </collision>
  </link>
  <joint name="left_knee_joint" type="revolute">
    <origin xyz="-0.078292 -0.0017335 -0.177225" rpy="0 0.5096 0"/>
    <parent link="left_hip_yaw_link"/>
    <child link="left_knee_link"/>
    <axis xyz="0 1 0"/>
    <limit lower="-0.33489" upper="2.5449" effort="139" velocity="20"/>
  <dynamics damping="0.0" friction="0.01"/><dynamics damping="0.0" friction="0.01"/></joint>
  <link name="left_ankle_pitch_link">
    <inertial>
      <origin xyz="-0.007269 0 0.011137" rpy="0 0 0"/>
      <mass value="0.074"/>
      <inertia ixx="8.4E-06" ixy="0" ixz="-2.9E-06" iyy="1.89E-05" iyz="0" izz="1.26E-05"/>
    </inertial>
    <visual>
      <origin xyz="0 0 0" rpy="0 0 0"/>
      <geometry>
        <mesh filename="package://gz_sim/meshes/g1/left_ankle_pitch_link.STL"/>
      </geometry>
      <material name="white">
        <color rgba="0.7 0.7 0.7 1"/>
      </material>
    </visual>
    <collision>
      <origin xyz="0 0 0" rpy="0 0 0"/>
      <geometry>
        <mesh filename="package://gz_sim/meshes/g1/left_ankle_pitch_link.STL"/>
      </geometry>
    </collision>
  </link>
  <joint name="left_ankle_pitch_joint" type="revolute">
    <origin xyz="0 0.0040687 -0.30007" rpy="0 -0.16053 0"/>
    <parent link="left_knee_link"/>
    <child link="left_ankle_pitch_link"/>
    <axis xyz="0 1 0"/>
    <limit lower="-0.68" upper="0.73" effort="40" velocity="53"/>
  <dynamics damping="0.0" friction="0.01"/><dynamics damping="0.0" friction="0.01"/></joint>
  <link name="left_ankle_roll_link">
    <inertial>
      <origin xyz="0.024762 2E-05 -0.012526" rpy="0 0 0"/>
      <mass value="0.391"/>
      <inertia ixx="0.0001552" ixy="-1E-07" ixz="7.51E-05" iyy="0.0010657" iyz="1E-07" izz="0.001098"/>
    </inertial>
    <visual>
      <origin xyz="0 0 0" rpy="0 0 0"/>
      <geometry>
        <mesh filename="package://gz_sim/meshes/g1/left_ankle_roll_link.STL"/>
      </geometry>
      <material name="dark">
        <color rgba="0.2 0.2 0.2 1"/>
      </material>
    </visual>
    <collision>
      <origin xyz="0.03703 0 -0.007354" rpy="0 0 0"/>
      <geometry>
            <box size="0.25234 0.08704 0.05874"/>
      </geometry>
    </collision>
    <!-- <collision>
      <origin xyz="-0.06 0.02 -0.03" rpy="0 0 0"/>
      <geometry>
        <sphere radius="0.001"/>
      </geometry>
    </collision>
    <collision>
      <origin xyz="-0.06 -0.02 -0.03" rpy="0 0 0"/>
      <geometry>
        <sphere radius="0.001"/>
      </geometry>
    </collision>
    <collision>
      <origin xyz="0.13 0.02 -0.03" rpy="0 0 0"/>
      <geometry>
        <sphere radius="0.001"/>
      </geometry>
    </collision>
    <collision>
      <origin xyz="0.13 -0.02 -0.03" rpy="0 0 0"/>
      <geometry>
        <sphere radius="0.001"/>
      </geometry>
    </collision> -->
  </link>
  <joint name="left_ankle_roll_joint" type="revolute">
    <origin xyz="0 0 -0.017558" rpy="0 0 0"/>
    <parent link="left_ankle_pitch_link"/>
    <child link="left_ankle_roll_link"/>
    <axis xyz="1 0 0"/>
    <limit lower="-0.2618" upper="0.2618" effort="40" velocity="53"/>
  <dynamics damping="0.0" friction="0.01"/><dynamics damping="0.0" friction="0.01"/></joint>
  <link name="right_hip_pitch_link">
    <inertial>
      <origin xyz="0.001962 -0.049392 -0.000941" rpy="0 0 0"/>
      <mass value="1.299"/>
      <inertia ixx="0.0013873" ixy="1.63E-05" ixz="-1E-06" iyy="0.0009059" iyz="4.24E-05" izz="0.0009196"/>
    </inertial>
    <visual>
      <origin xyz="0 0 0" rpy="0 0 0"/>
      <geometry>
        <mesh filename="package://gz_sim/meshes/g1/right_hip_pitch_link.STL"/>
      </geometry>
      <material name="dark">
        <color rgba="0.2 0.2 0.2 1"/>
      </material>
    </visual>
    <collision>
      <origin xyz="0 0 0" rpy="0 0 0"/>
      <geometry>
        <mesh filename="package://gz_sim/meshes/g1/right_hip_pitch_link.STL"/>
      </geometry>
    </collision>
  </link>
  <joint name="right_hip_pitch_joint" type="revolute">
    <origin xyz="0 -0.06445 -0.1027" rpy="0 -0.34907 0"/>
    <parent link="pelvis"/>
    <child link="right_hip_pitch_link"/>
    <axis xyz="0 1 0"/>
    <limit lower="-2.35" upper="3.05" effort="88" velocity="32"/>
  <dynamics damping="0.0" friction="0.01"/><dynamics damping="0.0" friction="0.01"/></joint>
  <link name="right_hip_roll_link">
    <inertial>
      <origin xyz="0.024757 0.001036 -0.086323" rpy="0 0 0"/>
      <mass value="1.446"/>
      <inertia ixx="0.0022702" ixy="3.7E-06" ixz="-0.0003789" iyy="0.002304" iyz="1.8E-05" izz="0.0016001"/>
    </inertial>
    <visual>
      <origin xyz="0 0 0" rpy="0 0 0"/>
      <geometry>
        <mesh filename="package://gz_sim/meshes/g1/right_hip_roll_link.STL"/>
      </geometry>
      <material name="white">
        <color rgba="0.7 0.7 0.7 1"/>
      </material>
    </visual>
    <collision>
      <origin xyz="0 0 0" rpy="0 0 0"/>
      <geometry>
        <mesh filename="package://gz_sim/meshes/g1/right_hip_roll_link.STL"/>
      </geometry>
    </collision>
  </link>
  <joint name="right_hip_roll_joint" type="revolute">
    <origin xyz="0 -0.0523 0" rpy="0 0 0"/>
    <parent link="right_hip_pitch_link"/>
    <child link="right_hip_roll_link"/>
    <axis xyz="1 0 0"/>
    <limit lower="-2.53" upper="0.26" effort="88" velocity="32"/>
  <dynamics damping="0.0" friction="0.01"/><dynamics damping="0.0" friction="0.01"/></joint>
  <link name="right_hip_yaw_link">
    <inertial>
      <origin xyz="-0.053554 0.011477 -0.14067" rpy="0 0 0"/>
      <mass value="2.052"/>
      <inertia ixx="0.0087264" ixy="0.0004402" ixz="-0.0036676" iyy="0.011374" iyz="0.0006654" izz="0.004279"/>
    </inertial>
    <visual>
      <origin xyz="0 0 0" rpy="0 0 0"/>
      <geometry>
        <mesh filename="package://gz_sim/meshes/g1/right_hip_yaw_link.STL"/>
      </geometry>
      <material name="white">
        <color rgba="0.7 0.7 0.7 1"/>
      </material>
    </visual>
    <collision>
      <origin xyz="0 0 0" rpy="0 0 0"/>
      <geometry>
        <mesh filename="package://gz_sim/meshes/g1/right_hip_yaw_link.STL"/>
      </geometry>
    </collision>
  </link>
  <joint name="right_hip_yaw_joint" type="revolute">
    <origin xyz="0.01966 0.0012139 -0.1241" rpy="0 0 0"/>
    <parent link="right_hip_roll_link"/>
    <child link="right_hip_yaw_link"/>
    <axis xyz="0 0 1"/>
    <limit lower="-2.75" upper="2.75" effort="88" velocity="32"/>
  <dynamics damping="0.0" friction="0.01"/><dynamics damping="0.0" friction="0.01"/></joint>
  <link name="right_knee_link">
    <inertial>
      <origin xyz="0.005505 -0.006534 -0.116629" rpy="0 0 0"/>
      <mass value="2.252"/>
      <inertia ixx="0.012443837" ixy="-0.000053496" ixz="-0.000437641" iyy="0.012674902" iyz="0.000682499" izz="0.001986501"/>
    </inertial>
    <visual>
      <origin xyz="0 0 0" rpy="0 0 0"/>
      <geometry>
        <mesh filename="package://gz_sim/meshes/g1/right_knee_link.STL"/>
      </geometry>
      <material name="white">
        <color rgba="0.7 0.7 0.7 1"/>
      </material>
    </visual>
    <collision>
      <origin xyz="0.007 -0.005 -0.15" rpy="0 0 0"/>
      <geometry>
        <cylinder radius="0.015" length="0.15"/>
      </geometry>
    </collision>
  </link>
  <joint name="right_knee_joint" type="revolute">
    <origin xyz="-0.078292 0.0017335 -0.177225" rpy="0 0.5096 0"/>
    <parent link="right_hip_yaw_link"/>
    <child link="right_knee_link"/>
    <axis xyz="0 1 0"/>
    <limit lower="-0.33489" upper="2.5449" effort="139" velocity="20"/>
  <dynamics damping="0.0" friction="0.01"/><dynamics damping="0.0" friction="0.01"/></joint>
  <link name="right_ankle_pitch_link">
    <inertial>
      <origin xyz="-0.007269 0 0.011137" rpy="0 0 0"/>
      <mass value="0.074"/>
      <inertia ixx="8.4E-06" ixy="0" ixz="-2.9E-06" iyy="1.89E-05" iyz="0" izz="1.26E-05"/>
    </inertial>
    <visual>
      <origin xyz="0 0 0" rpy="0 0 0"/>
      <geometry>
        <mesh filename="package://gz_sim/meshes/g1/right_ankle_pitch_link.STL"/>
      </geometry>
      <material name="white">
        <color rgba="0.7 0.7 0.7 1"/>
      </material>
    </visual>
    <collision>
      <origin xyz="0 0 0" rpy="0 0 0"/>
      <geometry>
        <mesh filename="package://gz_sim/meshes/g1/right_ankle_pitch_link.STL"/>
      </geometry>
    </collision>
  </link>
  <joint name="right_ankle_pitch_joint" type="revolute">
    <origin xyz="0 -0.0040687 -0.30007" rpy="0 -0.16053 0"/>
    <parent link="right_knee_link"/>
    <child link="right_ankle_pitch_link"/>
    <axis xyz="0 1 0"/>
    <limit lower="-0.68" upper="0.73" effort="40" velocity="53"/>
  <dynamics damping="0.0" friction="0.01"/><dynamics damping="0.0" friction="0.01"/></joint>
  <link name="right_ankle_roll_link">
    <inertial>
      <origin xyz="0.024762 -2E-05 -0.012526" rpy="0 0 0"/>
      <mass value="0.391"/>
      <inertia ixx="0.0001552" ixy="1E-07" ixz="7.51E-05" iyy="0.0010657" iyz="-1E-07" izz="0.001098"/>
    </inertial>
    <visual>
      <origin xyz="0 0 0" rpy="0 0 0"/>
      <geometry>
        <mesh filename="package://gz_sim/meshes/g1/right_ankle_roll_link.STL"/>
      </geometry>
      <material name="dark">
        <color rgba="0.2 0.2 0.2 1"/>
      </material>
    </visual>
    <collision>
      <origin xyz="0.03703 0 -0.007354" rpy="0 0 0"/>
      <geometry>
            <box size="0.25234 0.08704 0.05874"/>
      </geometry>
    </collision>
    <!-- <collision>
      <origin xyz="-0.06 0.02 -0.03" rpy="0 0 0"/>
      <geometry>
        <sphere radius="0.001"/>
      </geometry>
    </collision>
    <collision>
      <origin xyz="-0.06 -0.02 -0.03" rpy="0 0 0"/>
      <geometry>
        <sphere radius="0.001"/>
      </geometry>
    </collision>
    <collision>
      <origin xyz="0.13 0.02 -0.03" rpy="0 0 0"/>
      <geometry>
        <sphere radius="0.001"/>
      </geometry>
    </collision>
    <collision>
      <origin xyz="0.13 -0.02 -0.03" rpy="0 0 0"/>
      <geometry>
        <sphere radius="0.001"/>
      </geometry>
    </collision> -->
  </link>
  <joint name="right_ankle_roll_joint" type="revolute">
    <origin xyz="0 0 -0.017558" rpy="0 0 0"/>
    <parent link="right_ankle_pitch_link"/>
    <child link="right_ankle_roll_link"/>
    <axis xyz="1 0 0"/>
    <limit lower="-0.2618" upper="0.2618" effort="40" velocity="53"/>
  <dynamics damping="0.0" friction="0.01"/><dynamics damping="0.0" friction="0.01"/></joint>

  <!-- Torso -->
  <link name="torso_link">
    <inertial>
      <origin xyz="0.00197122283 0.00266902037 0.16936510960" rpy="0 0 0"/>
      <mass value="6.33959811"/>
      <inertia ixx="0.06037082109027" ixy="-0.00010168407055" ixz="0.00069845018092" iyy="0.04355153796551" iyz="0.00034366422728" izz="0.03339981866010"/>
    </inertial>
    <visual>
      <origin xyz="0 0 0" rpy="0 0 0"/>
      <geometry>
        <mesh filename="package://gz_sim/meshes/g1/torso_link.STL"/>
      </geometry>
      <material name="white">
        <color rgba="0.7 0.7 0.7 1"/>
      </material>
    </visual>
    <collision>
      <origin xyz="0 0 0" rpy="0 0 0"/>
      <geometry>
        <mesh filename="package://gz_sim/meshes/g1/torso_link.STL"/>
      </geometry>
    </collision>
  </link>
  <joint name="torso_joint" type="revolute">
    <origin xyz="0 0 0" rpy="0 0 0"/>
    <parent link="pelvis"/>
    <child link="torso_link"/>
    <axis xyz="0 0 1"/>
    <limit lower="-2.618" upper="2.618" effort="88" velocity="32"/>
  <dynamics damping="0.0" friction="0.01"/><dynamics damping="0.0" friction="0.01"/></joint>

  <!-- Head -->
  <link name="head_link">
    <inertial>
      <origin xyz="0.00138066852 0.00028430950 0.42034187824" rpy="0 0 0"/>
      <mass value="1.17976522"/>
      <inertia ixx="0.00543236042361" ixy="0.00000140137425" ixz="0.00034554752228" iyy="0.00552885306699" iyz="0.00001501216392" izz="0.00165378108136"/>
    </inertial>
    <visual>
      <origin xyz="0 0 0" rpy="0 0 0"/>
      <geometry>
        <mesh filename="package://gz_sim/meshes/g1/head_link.STL"/>
      </geometry>
      <material name="dark">
        <color rgba="0.2 0.2 0.2 1"/>
      </material>
    </visual>
    <collision>
      <origin xyz="0 0 0" rpy="0 0 0"/>
      <geometry>
        <mesh filename="package://gz_sim/meshes/g1/head_link.STL"/>
      </geometry>
    </collision>
  </link>
  <joint name="head_joint" type="fixed">
    <origin xyz="0 0 0" rpy="0 0 0"/>
    <parent link="torso_link"/>
    <child link="head_link"/>
  <dynamics damping="0.0" friction="0.01"/><dynamics damping="0.0" friction="0.01"/></joint>

  <!-- L ARM -->
  <link name="left_shoulder_pitch_link">
    <inertial>
      <origin xyz="-0.001431 0.048811 0.001304" rpy="0 0 0"/>
      <mass value="0.713"/>
      <inertia ixx="0.0004614" ixy="-9.3E-06" ixz="1E-05" iyy="0.0004146" iyz="5.5E-06" izz="0.0004416"/>
    </inertial>
    <visual>
      <origin xyz="0 0 0" rpy="0 0 0"/>
      <geometry>
        <mesh filename="package://gz_sim/meshes/g1/left_shoulder_pitch_link.STL"/>
      </geometry>
      <material name="white">
        <color rgba="0.7 0.7 0.7 1"/>
      </material>
    </visual>
    <collision>
      <origin xyz="0 0 0" rpy="0 0 0"/>
      <geometry>
        <mesh filename="package://gz_sim/meshes/g1/left_shoulder_pitch_link.STL"/>
      </geometry>
    </collision>
  </link>
  <joint name="left_shoulder_pitch_joint" type="revolute">
    <origin xyz="-0.0025 0.10396 0.25928" rpy="0.27925 0 0"/>
    <parent link="torso_link"/>
    <child link="left_shoulder_pitch_link"/>
    <axis xyz="0 1 0"/>
    <limit lower="-2.9671" upper="2.7925" effort="21" velocity="53"/>
  <dynamics damping="0.0" friction="0.01"/><dynamics damping="0.0" friction="0.01"/></joint>
  <link name="left_shoulder_roll_link">
    <inertial>
      <origin xyz="-0.003415 0.006955 -0.064598" rpy="0 0 0"/>
      <mass value="0.642"/>
      <inertia ixx="0.0006159" ixy="0" ixz="-5.6E-06" iyy="0.0006835" iyz="2.1E-06" izz="0.000373"/>
    </inertial>
    <visual>
      <origin xyz="0 0 0" rpy="0 0 0"/>
      <geometry>
        <mesh filename="package://gz_sim/meshes/g1/left_shoulder_roll_link.STL"/>
      </geometry>
      <material name="white">
        <color rgba="0.7 0.7 0.7 1"/>
      </material>
    </visual>
    <collision>
      <origin xyz="-0.004 0.006 -0.053" rpy="0 0 0"/>
      <geometry>
        <cylinder radius="0.03" length="0.03"/>
      </geometry>
    </collision>
  </link>
  <joint name="left_shoulder_roll_joint" type="revolute">
    <origin xyz="0 0.052 0" rpy="-0.27925 0 0"/>
    <parent link="left_shoulder_pitch_link"/>
    <child link="left_shoulder_roll_link"/>
    <axis xyz="1 0 0"/>
    <limit lower="-1.5882" upper="2.2515" effort="21" velocity="53"/>
  <dynamics damping="0.0" friction="0.01"/><dynamics damping="0.0" friction="0.01"/></joint>
  <link name="left_shoulder_yaw_link">
    <inertial>
      <origin xyz="0.000375 -0.00444 -0.072374" rpy="0 0 0"/>
      <mass value="0.713"/>
      <inertia ixx="0.0009699" ixy="7.1E-06" ixz="7.8E-06" iyy="0.0009691" iyz="-4.49E-05" izz="0.0003826"/>
    </inertial>
    <visual>
      <origin xyz="0 0 0" rpy="0 0 0"/>
      <geometry>
        <mesh filename="package://gz_sim/meshes/g1/left_shoulder_yaw_link.STL"/>
      </geometry>
      <material name="white">
        <color rgba="0.7 0.7 0.7 1"/>
      </material>
    </visual>
    <collision>
      <origin xyz="0 0 0" rpy="0 0 0"/>
      <geometry>
        <mesh filename="package://gz_sim/meshes/g1/left_shoulder_yaw_link.STL"/>
      </geometry>
    </collision>
  </link>
  <joint name="left_shoulder_yaw_joint" type="revolute">
    <origin xyz="-0.00354 0.0062424 -0.1032" rpy="0 0 0"/>
    <parent link="left_shoulder_roll_link"/>
    <child link="left_shoulder_yaw_link"/>
    <axis xyz="0 0 1"/>
    <limit lower="-2.618" upper="2.618" effort="21" velocity="53"/>
  <dynamics damping="0.0" friction="0.01"/><dynamics damping="0.0" friction="0.01"/></joint>
  <link name="left_elbow_pitch_link">
    <inertial>
      <origin xyz="0.064497 0.002873 0" rpy="0 0 0"/>
      <mass value="0.601"/>
      <inertia ixx="0.0002845" ixy="8.06E-05" ixz="9E-09" iyy="0.0004647" iyz="5E-09" izz="0.0004712"/>
    </inertial>
    <visual>
      <origin xyz="0 0 0" rpy="0 0 0"/>
      <geometry>
        <mesh filename="package://gz_sim/meshes/g1/left_elbow_pitch_link.STL"/>
      </geometry>
      <material name="white">
        <color rgba="0.7 0.7 0.7 1"/>
      </material>
    </visual>
    <collision>
      <origin xyz="0 0 0" rpy="0 0 0"/>
      <geometry>
        <mesh filename="package://gz_sim/meshes/g1/left_elbow_pitch_link.STL"/>
      </geometry>
    </collision>
  </link>
  <joint name="left_elbow_pitch_joint" type="revolute">
    <origin xyz="0 0.00189 -0.0855" rpy="0 0 0"/>
    <parent link="left_shoulder_yaw_link"/>
    <child link="left_elbow_pitch_link"/>
    <axis xyz="0 1 0"/>
    <limit lower="-0.2268" upper="3.4208" effort="21" velocity="53"/>
  <dynamics damping="0.0" friction="0.01"/><dynamics damping="0.0" friction="0.01"/></joint>
  <link name="left_elbow_roll_link">
    <inertial>
      <origin xyz="0.081811 0.001454 0.001" rpy="0 0 0"/>
      <mass value="0.227"/>
      <inertia ixx="0.0001093" ixy="-1.55E-05" ixz="-2.91E-05" iyy="0.000977" iyz="1E-06" izz="0.0009676"/>
    </inertial>
    <visual>
      <origin xyz="0 0 0" rpy="0 0 0"/>
      <geometry>
        <mesh filename="package://gz_sim/meshes/g1/left_elbow_roll_link.STL"/>
      </geometry>
      <material name="white">
        <color rgba="0.7 0.7 0.7 1"/>
      </material>
    </visual>
    <collision>
      <origin xyz="0 0 0" rpy="0 0 0"/>
      <geometry>
        <mesh filename="package://gz_sim/meshes/g1/left_elbow_roll_link.STL"/>
      </geometry>
    </collision>
  </link>
  <joint name="left_elbow_roll_joint" type="revolute">
    <origin xyz="0.1 0 0" rpy="0 0 0"/>
    <parent link="left_elbow_pitch_link"/>
    <child link="left_elbow_roll_link"/>
    <axis xyz="1 0 0"/>
    <limit lower="-2.0943" upper="2.0943" effort="21" velocity="53"/>
  <dynamics damping="0.0" friction="0.01"/><dynamics damping="0.0" friction="0.01"/></joint>

  <!-- R ARM -->
  <link name="right_shoulder_pitch_link">
    <inertial>
      <origin xyz="-0.001431 -0.048811 0.001304" rpy="0 0 0"/>
      <mass value="0.713"/>
      <inertia ixx="0.0004614" ixy="9.3E-06" ixz="1E-05" iyy="0.0004146" iyz="-5.5E-06" izz="0.0004416"/>
    </inertial>
    <visual>
      <origin xyz="0 0 0" rpy="0 0 0"/>
      <geometry>
        <mesh filename="package://gz_sim/meshes/g1/right_shoulder_pitch_link.STL"/>
      </geometry>
      <material name="white">
        <color rgba="0.7 0.7 0.7 1"/>
      </material>
    </visual>
    <collision>
      <origin xyz="0 0 0" rpy="0 0 0"/>
      <geometry>
        <mesh filename="package://gz_sim/meshes/g1/right_shoulder_pitch_link.STL"/>
      </geometry>
    </collision>
  </link>
  <joint name="right_shoulder_pitch_joint" type="revolute">
    <origin xyz="-0.0025 -0.10396 0.25928" rpy="-0.27925 0 0"/>
    <parent link="torso_link"/>
    <child link="right_shoulder_pitch_link"/>
    <axis xyz="0 1 0"/>
    <limit lower="-2.9671" upper="2.7925" effort="21" velocity="53"/>
  <dynamics damping="0.0" friction="0.01"/><dynamics damping="0.0" friction="0.01"/></joint>
  <link name="right_shoulder_roll_link">
    <inertial>
      <origin xyz="-0.003415 -0.006955 -0.064598" rpy="0 0 0"/>
      <mass value="0.642"/>
      <inertia ixx="0.0006159" ixy="0" ixz="-5.6E-06" iyy="0.0006835" iyz="-2.1E-06" izz="0.000373"/>
    </inertial>
    <visual>
      <origin xyz="0 0 0" rpy="0 0 0"/>
      <geometry>
        <mesh filename="package://gz_sim/meshes/g1/right_shoulder_roll_link.STL"/>
      </geometry>
      <material name="white">
        <color rgba="0.7 0.7 0.7 1"/>
      </material>
    </visual>
    <collision>
      <origin xyz="-0.004 -0.006 -0.053" rpy="0 0 0"/>
      <geometry>
        <cylinder radius="0.03" length="0.03"/>
      </geometry>
    </collision>
  </link>
  <joint name="right_shoulder_roll_joint" type="revolute">
    <origin xyz="0 -0.052 0" rpy="0.27925 0 0"/>
    <parent link="right_shoulder_pitch_link"/>
    <child link="right_shoulder_roll_link"/>
    <axis xyz="1 0 0"/>
    <limit lower="-2.2515" upper="1.5882" effort="21" velocity="53"/>
  <dynamics damping="0.0" friction="0.01"/><dynamics damping="0.0" friction="0.01"/></joint>
  <link name="right_shoulder_yaw_link">
    <inertial>
      <origin xyz="0.000375 0.00444 -0.072374" rpy="0 0 0"/>
      <mass value="0.713"/>
      <inertia ixx="0.0009699" ixy="-7.1E-06" ixz="7.8E-06" iyy="0.0009691" iyz="4.49E-05" izz="0.0003826"/>
    </inertial>
    <visual>
      <origin xyz="0 0 0" rpy="0 0 0"/>
      <geometry>
        <mesh filename="package://gz_sim/meshes/g1/right_shoulder_yaw_link.STL"/>
      </geometry>
      <material name="white">
        <color rgba="0.7 0.7 0.7 1"/>
      </material>
    </visual>
    <collision>
      <origin xyz="0 0 0" rpy="0 0 0"/>
      <geometry>
        <mesh filename="package://gz_sim/meshes/g1/right_shoulder_yaw_link.STL"/>
      </geometry>
    </collision>
  </link>
  <joint name="right_shoulder_yaw_joint" type="revolute">
    <origin xyz="-0.00354 -0.0062424 -0.1032" rpy="0 0 0"/>
    <parent link="right_shoulder_roll_link"/>
    <child link="right_shoulder_yaw_link"/>
    <axis xyz="0 0 1"/>
    <limit lower="-2.618" upper="2.618" effort="21" velocity="53"/>
  <dynamics damping="0.0" friction="0.01"/><dynamics damping="0.0" friction="0.01"/></joint>
  <link name="right_elbow_pitch_link">
    <inertial>
      <origin xyz="0.064497 -0.002873 0" rpy="0 0 0"/>
      <mass value="0.601"/>
      <inertia ixx="0.0002845" ixy="-8.06E-05" ixz="9E-09" iyy="0.0004647" iyz="-5E-09" izz="0.0004712"/>
    </inertial>
    <visual>
      <origin xyz="0 0 0" rpy="0 0 0"/>
      <geometry>
        <mesh filename="package://gz_sim/meshes/g1/right_elbow_pitch_link.STL"/>
      </geometry>
      <material name="white">
        <color rgba="0.7 0.7 0.7 1"/>
      </material>
    </visual>
    <collision>
      <origin xyz="0 0 0" rpy="0 0 0"/>
      <geometry>
        <mesh filename="package://gz_sim/meshes/g1/right_elbow_pitch_link.STL"/>
      </geometry>
    </collision>
  </link>
  <joint name="right_elbow_pitch_joint" type="revolute">
    <origin xyz="0 -0.00189 -0.0855" rpy="0 0 0"/>
    <parent link="right_shoulder_yaw_link"/>
    <child link="right_elbow_pitch_link"/>
    <axis xyz="0 1 0"/>
    <limit lower="-0.2268" upper="3.4208" effort="21" velocity="53"/>
  <dynamics damping="0.0" friction="0.01"/><dynamics damping="0.0" friction="0.01"/></joint>
  <link name="right_elbow_roll_link">
    <inertial>
      <origin xyz="0.081811 -0.001454 0.001" rpy="0 0 0"/>
      <mass value="0.227"/>
      <inertia ixx="0.0001093" ixy="1.55E-05" ixz="-2.91E-05" iyy="0.000977" iyz="-1E-06" izz="0.0009676"/>
    </inertial>
    <visual>
      <origin xyz="0 0 0" rpy="0 0 0"/>
      <geometry>
        <mesh filename="package://gz_sim/meshes/g1/right_elbow_roll_link.STL"/>
      </geometry>
      <material name="white">
        <color rgba="0.7 0.7 0.7 1"/>
      </material>
    </visual>
    <collision>
      <origin xyz="0 0 0" rpy="0 0 0"/>
      <geometry>
        <mesh filename="package://gz_sim/meshes/g1/right_elbow_roll_link.STL"/>
      </geometry>
    </collision>
  </link>
  <joint name="right_elbow_roll_joint" type="revolute">
    <origin xyz="0.1 0 0" rpy="0 0 0"/>
    <parent link="right_elbow_pitch_link"/>
    <child link="right_elbow_roll_link"/>
    <axis xyz="1 0 0"/>
    <limit lower="-2.0943" upper="2.0943" effort="21" velocity="53"/>
  <dynamics damping="0.0" friction="0.01"/><dynamics damping="0.0" friction="0.01"/></joint>

  <!-- LOGO -->
  <joint name="logo_joint" type="fixed">
    <origin xyz="0 0 0" rpy="0 0 0"/>
    <parent link="torso_link"/>
    <child link="logo_link"/>
  <dynamics damping="0.0" friction="0.01"/><dynamics damping="0.0" friction="0.01"/></joint>
  <link name="logo_link">
    <inertial>
      <origin xyz="-0.00306556489 0.00005625032 0.24526459523" rpy="0 0 0"/>
      <mass value="0.001"/>
      <inertia ixx="0.00000089650105" ixy="0.00000007028325" ixz="0.00000002735427" iyy="0.00000644846110" iyz="0.00000000029738" izz="0.00000688611155"/>
    </inertial>
    <visual>
      <origin xyz="0 0 0" rpy="0 0 0"/>
      <geometry>
        <mesh filename="package://gz_sim/meshes/g1/logo_link.STL"/>
      </geometry>
      <material name="dark">
        <color rgba="0.2 0.2 0.2 1"/>
      </material>
    </visual>
    <collision>
      <origin xyz="0 0 0" rpy="0 0 0"/>
      <geometry>
        <mesh filename="package://gz_sim/meshes/g1/logo_link.STL"/>
      </geometry>
    </collision>
  </link>

  <!-- IMU -->
  <link name="imu_link"></link>
  <joint name="imu_joint" type="fixed">
    <origin xyz="-0.04233868314 0.00166 0.152067" rpy="0 0 0"/>
    <parent link="torso_link"/>
    <child link="imu_link"/>
  </joint>

  <!-- Gripper -->
  <joint name="left_palm_joint" type="fixed">
    <origin xyz="0.120 0 0" rpy="0 0 0"/>
    <parent link="left_elbow_roll_link"/>
    <child link="left_palm_link"/>
    <axis xyz="0 0 0"/>
  <dynamics damping="0.0" friction="0.01"/></joint>
  <link name="left_palm_link">
    <inertial>
      <origin xyz="0.05578422502 0.00148509387 -0.00032670143" rpy="0 0 0"/>
      <mass value="0.28126043"/>
      <inertia ixx="0.00017638101047" ixy="-0.00000652171140" ixz="0.00000021301775" iyy="0.00031084250366" iyz="0.00000000708018" izz="0.00018939350451"/>
    </inertial>
    <visual>
      <origin xyz="0 0 0" rpy="0 0 0"/>
      <geometry>
        <mesh filename="package://gz_sim/meshes/g1/left_palm_link.STL"/>
      </geometry>
      <material name="white">
        <color rgba="0.7 0.7 0.7 1"/>
      </material>
    </visual>
    <collision>
      <origin xyz="0 0 0" rpy="0 0 0"/>
      <geometry>
        <mesh filename="package://gz_sim/meshes/g1/left_palm_link.STL"/>
      </geometry>
    </collision>
  </link>
  <joint name="left_zero_joint" type="revolute">
    <origin xyz="0.050 0 0" rpy="0 0 0"/>
    <parent link="left_palm_link"/>
    <child link="left_zero_link"/>
    <axis xyz="0 1 0"/>
    <limit effort="0.7" velocity="23" lower="-0.523598" upper="0.523598"/>
  <dynamics damping="0.0" friction="0.01"/></joint>
  <link name="left_zero_link">
    <inertial>
      <origin xyz="-0.02604664462 -0.00877511180 0.00001086048" rpy="0 0 0"/>
      <mass value="0.05098927"/>
      <inertia ixx="0.00000679821860" ixy="-0.00000098281498" ixz="-0.00000000406407" iyy="0.00000501631802" iyz="0.00000002833450" izz="0.00000868017156"/>
    </inertial>
    <visual>
      <origin xyz="0 0 0" rpy="0 0 0"/>
      <geometry>
        <mesh filename="package://gz_sim/meshes/g1/left_zero_link.STL"/>
      </geometry>
      <material name="white">
        <color rgba="0.7 0.7 0.7 1"/>
      </material>
    </visual>
    <!-- <collision>
      <origin xyz="0 0 0" rpy="0 0 0"/>
      <geometry>
        <mesh filename="package://gz_sim/meshes/g1/left_zero_link.STL"/>
      </geometry>
    </collision> -->
  </link>
  <joint name="left_one_joint" type="revolute">
    <origin xyz="-0.02652502957 -0.0188 -0.00005" rpy="0 0 0"/>
    <parent link="left_zero_link"/>
    <child link="left_one_link"/>
    <axis xyz="0 0 1"/>
    <limit effort="0.7" velocity="23" lower="-1" upper="1.2"/>
  <dynamics damping="0.0" friction="0.01"/></joint>
  <link name="left_one_link">
    <inertial>
      <origin xyz="-0.00181538145 -0.03270571529 -0.00018587117" rpy="0 0 0"/>
      <mass value="0.04776204"/>
      <inertia ixx="0.00000800634866" ixy="-0.00000020811350" ixz="-0.00000004687654" iyy="0.00000366333777" iyz="0.00000005133915" izz="0.00000785913677"/>
    </inertial>
    <visual>
      <origin xyz="0 0 0" rpy="0 0 0"/>
      <geometry>
        <mesh filename="package://gz_sim/meshes/g1/left_one_link.STL"/>
      </geometry>
      <material name="white">
        <color rgba="0.7 0.7 0.7 1"/>
      </material>
    </visual>
    <collision>
      <origin xyz="-0.001 -0.032 0" rpy="0 0 0"/>
      <geometry>
        <box size="0.02 0.03 0.02"/>
      </geometry>
    </collision>
  </link>
  <joint name="left_two_joint" type="revolute">
    <origin xyz="0 -0.0431 0" rpy="0 0 0"/>
    <parent link="left_one_link"/>
    <child link="left_two_link"/>
    <axis xyz="0 0 1"/>
    <limit effort="0.7" velocity="23" lower="0" upper="1.84"/>
  <dynamics damping="0.0" friction="0.01"/></joint>
  <link name="left_two_link">
    <inertial>
      <origin xyz="-0.00135257289 -0.02375910756 -0.00011966865" rpy="0 0 0"/>
      <mass value="0.01385835"/>
      <inertia ixx="0.00000254698095" ixy="-0.00000010086310" ixz="-0.00000000325710" iyy="0.00000094744556" iyz="0.00000003605469" izz="0.00000204288618"/>
    </inertial>
    <visual>
      <origin xyz="0 0 0" rpy="0 0 0"/>
      <geometry>
        <mesh filename="package://gz_sim/meshes/g1/left_two_link.STL"/>
      </geometry>
      <material name="white">
        <color rgba="0.7 0.7 0.7 1"/>
      </material>
    </visual>
    <collision>
      <origin xyz="0 0 0" rpy="0 0 0"/>
      <geometry>
        <mesh filename="package://gz_sim/meshes/g1/left_two_link.STL"/>
      </geometry>
    </collision>
  </link>
  <joint name="left_three_joint" type="revolute">
    <origin xyz="0.085 0.004 0.02395" rpy="0 0 0"/>
    <parent link="left_palm_link"/>
    <child link="left_three_link"/>
    <axis xyz="0 0 1"/>
    <limit effort="0.7" velocity="23" lower="-1.84" upper="0.3"/>
  <dynamics damping="0.0" friction="0.01"/></joint>
  <link name="left_three_link">
    <inertial>
      <origin xyz="0.03625612321 -0.00157250459 0.00026989918" rpy="0 0 0"/>
      <mass value="0.04884689"/>
      <inertia ixx="0.00000383218469" ixy="0.00000003239984" ixz="0.00000001923377" iyy="0.00000890974599" iyz="-0.00000004429800" izz="0.00000865612355"/>
    </inertial>
    <visual>
      <origin xyz="0 0 0" rpy="0 0 0"/>
      <geometry>
        <mesh filename="package://gz_sim/meshes/g1/left_three_link.STL"/>
      </geometry>
      <material name="white">
        <color rgba="0.7 0.7 0.7 1"/>
      </material>
    </visual>
    <collision>
      <origin xyz="0 0 0" rpy="0 0 0"/>
      <geometry>
        <mesh filename="package://gz_sim/meshes/g1/left_three_link.STL"/>
      </geometry>
    </collision>
  </link>
  <joint name="left_four_joint" type="revolute">
    <origin xyz="0.0471 -0.0036 0" rpy="0 0 0"/>
    <parent link="left_three_link"/>
    <child link="left_four_link"/>
    <axis xyz="0 0 1"/>
    <limit effort="0.7" velocity="23" lower="-1.84" upper="0"/>
  <dynamics damping="0.0" friction="0.01"/></joint>
  <link name="left_four_link">
    <inertial>
      <origin xyz="0.02375910756 0.00135257289 0.00011966865" rpy="0 0 0"/>
      <mass value="0.01385835"/>
      <inertia ixx="0.00000094744556" ixy="-0.00000010086310" ixz="0.00000003605469" iyy="0.00000254698095" iyz="-0.00000000325710" izz="0.00000204288618"/>
    </inertial>
    <visual>
      <origin xyz="0 0 0" rpy="0 0 0"/>
      <geometry>
        <mesh filename="package://gz_sim/meshes/g1/left_four_link.STL"/>
      </geometry>
      <material name="white">
        <color rgba="0.7 0.7 0.7 1"/>
      </material>
    </visual>
    <collision>
      <origin xyz="0 0 0" rpy="0 0 0"/>
      <geometry>
        <mesh filename="package://gz_sim/meshes/g1/left_four_link.STL"/>
      </geometry>
    </collision>
  </link>
  <joint name="left_five_joint" type="revolute">
    <origin xyz="0.085 0.004 -0.02395" rpy="0 0 0"/>
    <parent link="left_palm_link"/>
    <child link="left_five_link"/>
    <axis xyz="0 0 1"/>
    <limit effort="0.7" velocity="23" lower="-1.84" upper="0.3"/>
  <dynamics damping="0.0" friction="0.01"/></joint>
  <link name="left_five_link">
    <inertial>
      <origin xyz="0.03625612321 -0.00157250459 0.00026989918" rpy="0 0 0"/>
      <mass value="0.04884689"/>
      <inertia ixx="0.00000383218469" ixy="0.00000003239984" ixz="0.00000001923377" iyy="0.00000890974599" iyz="-0.00000004429800" izz="0.00000865612355"/>
    </inertial>
    <visual>
      <origin xyz="0 0 0" rpy="0 0 0"/>
      <geometry>
        <mesh filename="package://gz_sim/meshes/g1/left_five_link.STL"/>
      </geometry>
      <material name="white">
        <color rgba="0.7 0.7 0.7 1"/>
      </material>
    </visual>
    <collision>
      <origin xyz="0 0 0" rpy="0 0 0"/>
      <geometry>
        <mesh filename="package://gz_sim/meshes/g1/left_five_link.STL"/>
      </geometry>
    </collision>
  </link>
  <joint name="left_six_joint" type="revolute">
    <origin xyz="0.0471 -0.0036 0" rpy="0 0 0"/>
    <parent link="left_five_link"/>
    <child link="left_six_link"/>
    <axis xyz="0 0 1"/>
    <limit effort="0.7" velocity="23" lower="-1.84" upper="0"/>
  <dynamics damping="0.0" friction="0.01"/></joint>
  <link name="left_six_link">
    <inertial>
      <origin xyz="0.02375910756 0.00135257289 0.00011966865" rpy="0 0 0"/>
      <mass value="0.01385835"/>
      <inertia ixx="0.00000094744556" ixy="-0.00000010086310" ixz="0.00000003605469" iyy="0.00000254698095" iyz="-0.00000000325710" izz="0.00000204288618"/>
    </inertial>
    <visual>
      <origin xyz="0 0 0" rpy="0 0 0"/>
      <geometry>
        <mesh filename="package://gz_sim/meshes/g1/left_six_link.STL"/>
      </geometry>
      <material name="white">
        <color rgba="0.7 0.7 0.7 1"/>
      </material>
    </visual>
    <collision>
      <origin xyz="0 0 0" rpy="0 0 0"/>
      <geometry>
        <mesh filename="package://gz_sim/meshes/g1/left_six_link.STL"/>
      </geometry>
    </collision>
  </link>


  <joint name="right_palm_joint" type="fixed">
    <origin xyz="0.120 0 0" rpy="0 0 0"/>
    <parent link="right_elbow_roll_link"/>
    <child link="right_palm_link"/>
    <axis xyz="0 0 0"/>
  <dynamics damping="0.0" friction="0.01"/></joint>
  <link name="right_palm_link">
    <inertial>
      <origin xyz="0.05578422502 -0.00148509387 -0.00032670143" rpy="0 0 0"/>
      <mass value="0.28126043"/>
      <inertia ixx="0.00017638101047" ixy="0.00000652171140" ixz="0.00000021301775" iyy="0.00031084250366" iyz="-0.00000000708018" izz="0.00018939350451"/>
    </inertial>
    <visual>
      <origin xyz="0 0 0" rpy="0 0 0"/>
      <geometry>
        <mesh filename="package://gz_sim/meshes/g1/right_palm_link.STL"/>
      </geometry>
      <material name="white">
        <color rgba="0.7 0.7 0.7 1"/>
      </material>
    </visual>
    <collision>
      <origin xyz="0 0 0" rpy="0 0 0"/>
      <geometry>
        <mesh filename="package://gz_sim/meshes/g1/right_palm_link.STL"/>
      </geometry>
    </collision>
  </link>
  <joint name="right_zero_joint" type="revolute">
    <origin xyz="0.050 0 0" rpy="0 0 0"/>
    <parent link="right_palm_link"/>
    <child link="right_zero_link"/>
    <axis xyz="0 1 0"/>
    <limit effort="0.7" velocity="23" lower="-0.523598" upper="0.523598"/>
  <dynamics damping="0.0" friction="0.01"/></joint>
  <link name="right_zero_link">
    <inertial>
      <origin xyz="-0.02604664462 0.00877511180 0.00001086048" rpy="0 0 0"/>
      <mass value="0.05098927"/>
      <inertia ixx="0.00000679821860" ixy="0.00000098281498" ixz="-0.00000000406407" iyy="0.00000501631802" iyz="-0.00000002833450" izz="0.00000868017156"/>
    </inertial>
    <visual>
      <origin xyz="0 0 0" rpy="0 0 0"/>
      <geometry>
        <mesh filename="package://gz_sim/meshes/g1/right_zero_link.STL"/>
      </geometry>
      <material name="white">
        <color rgba="0.7 0.7 0.7 1"/>
      </material>
    </visual>
    <!-- <collision>
      <origin xyz="0 0 0" rpy="0 0 0"/>
      <geometry>
        <mesh filename="package://gz_sim/meshes/g1/right_zero_link.STL"/>
      </geometry>
    </collision> -->
  </link>
  <joint name="right_one_joint" type="revolute">
    <origin xyz="-0.02652502957 0.0188 -0.00005" rpy="0 0 0"/>
    <parent link="right_zero_link"/>
    <child link="right_one_link"/>
    <axis xyz="0 0 1"/>
    <limit effort="0.7" velocity="23" lower="-1.2" upper="1"/>
  <dynamics damping="0.0" friction="0.01"/></joint>
  <link name="right_one_link">
    <inertial>
      <origin xyz="-0.00181538145 0.03270571529 -0.00018587117" rpy="0 0 0"/>
      <mass value="0.04776204"/>
      <inertia ixx="0.00000800634866" ixy="0.00000020811350" ixz="-0.00000004687654" iyy="0.00000366333777" iyz="-0.00000005133915" izz="0.00000785913677"/>
    </inertial>
    <visual>
      <origin xyz="0 0 0" rpy="0 0 0"/>
      <geometry>
        <mesh filename="package://gz_sim/meshes/g1/right_one_link.STL"/>
      </geometry>
      <material name="white">
        <color rgba="0.7 0.7 0.7 1"/>
      </material>
    </visual>
    <collision>
      <origin xyz="-0.001 0.032 0" rpy="0 0 0"/>
      <geometry>
        <box size="0.02 0.03 0.02"/>
      </geometry>
    </collision>
  </link>
  <joint name="right_two_joint" type="revolute">
    <origin xyz="0 0.0431 0" rpy="0 0 0"/>
    <parent link="right_one_link"/>
    <child link="right_two_link"/>
    <axis xyz="0 0 1"/>
    <limit effort="0.7" velocity="23" lower="-1.84" upper="0"/>
  <dynamics damping="0.0" friction="0.01"/></joint>
  <link name="right_two_link">
    <inertial>
      <origin xyz="-0.00135257289 0.02375910756 -0.00011966865" rpy="0 0 0"/>
      <mass value="0.01385835"/>
      <inertia ixx="0.00000254698095" ixy="0.00000010086310" ixz="-0.00000000325710" iyy="0.00000094744556" iyz="-0.00000003605469" izz="0.00000204288618"/>
    </inertial>
    <visual>
      <origin xyz="0 0 0" rpy="0 0 0"/>
      <geometry>
        <mesh filename="package://gz_sim/meshes/g1/right_two_link.STL"/>
      </geometry>
      <material name="white">
        <color rgba="0.7 0.7 0.7 1"/>
      </material>
    </visual>
    <collision>
      <origin xyz="0 0 0" rpy="0 0 0"/>
      <geometry>
        <mesh filename="package://gz_sim/meshes/g1/right_two_link.STL"/>
      </geometry>
    </collision>
  </link>
  <joint name="right_three_joint" type="revolute">
    <origin xyz="0.085 -0.004 0.02395" rpy="0 0 0"/>
    <parent link="right_palm_link"/>
    <child link="right_three_link"/>
    <axis xyz="0 0 1"/>
    <limit effort="0.7" velocity="23" lower="-0.3" upper="1.84"/>
  <dynamics damping="0.0" friction="0.01"/></joint>
  <link name="right_three_link">
    <inertial>
      <origin xyz="0.03625612321 0.00157250459 0.00026989918" rpy="0 0 0"/>
      <mass value="0.04884689"/>
      <inertia ixx="0.00000383218469" ixy="-0.00000003239984" ixz="0.00000001923377" iyy="0.00000890974599" iyz="0.00000004429800" izz="0.00000865612355"/>
    </inertial>
    <visual>
      <origin xyz="0 0 0" rpy="0 0 0"/>
      <geometry>
        <mesh filename="package://gz_sim/meshes/g1/right_three_link.STL"/>
      </geometry>
      <material name="white">
        <color rgba="0.7 0.7 0.7 1"/>
      </material>
    </visual>
    <collision>
      <origin xyz="0 0 0" rpy="0 0 0"/>
      <geometry>
        <mesh filename="package://gz_sim/meshes/g1/right_three_link.STL"/>
      </geometry>
    </collision>
  </link>
  <joint name="right_four_joint" type="revolute">
    <origin xyz="0.0471 0.0036 0" rpy="0 0 0"/>
    <parent link="right_three_link"/>
    <child link="right_four_link"/>
    <axis xyz="0 0 1"/>
    <limit effort="0.7" velocity="23" lower="0" upper="1.84"/>
  <dynamics damping="0.0" friction="0.01"/></joint>
  <link name="right_four_link">
    <inertial>
      <origin xyz="0.02375910756 -0.00135257289 0.00011966865" rpy="0 0 0"/>
      <mass value="0.01385835"/>
      <inertia ixx="0.00000094744556" ixy="0.00000010086310" ixz="0.00000003605469" iyy="0.00000254698095" iyz="0.00000000325710" izz="0.00000204288618"/>
    </inertial>
    <visual>
      <origin xyz="0 0 0" rpy="0 0 0"/>
      <geometry>
        <mesh filename="package://gz_sim/meshes/g1/right_four_link.STL"/>
      </geometry>
      <material name="white">
        <color rgba="0.7 0.7 0.7 1"/>
      </material>
    </visual>
    <collision>
      <origin xyz="0 0 0" rpy="0 0 0"/>
      <geometry>
        <mesh filename="package://gz_sim/meshes/g1/right_four_link.STL"/>
      </geometry>
    </collision>
  </link>
  <joint name="right_five_joint" type="revolute">
    <origin xyz="0.085 -0.004 -0.02395" rpy="0 0 0"/>
    <parent link="right_palm_link"/>
    <child link="right_five_link"/>
    <axis xyz="0 0 1"/>
    <limit effort="0.7" velocity="23" lower="-0.3" upper="1.84"/>
  <dynamics damping="0.0" friction="0.01"/></joint>
  <link name="right_five_link">
    <inertial>
      <origin xyz="0.03625612321 0.00157250459 0.00026989918" rpy="0 0 0"/>
      <mass value="0.04884689"/>
      <inertia ixx="0.00000383218469" ixy="-0.00000003239984" ixz="0.00000001923377" iyy="0.00000890974599" iyz="0.00000004429800" izz="0.00000865612355"/>
    </inertial>
    <visual>
      <origin xyz="0 0 0" rpy="0 0 0"/>
      <geometry>
        <mesh filename="package://gz_sim/meshes/g1/right_five_link.STL"/>
      </geometry>
      <material name="white">
        <color rgba="0.7 0.7 0.7 1"/>
      </material>
    </visual>
    <collision>
      <origin xyz="0 0 0" rpy="0 0 0"/>
      <geometry>
        <mesh filename="package://gz_sim/meshes/g1/right_five_link.STL"/>
      </geometry>
    </collision>
  </link>
  <joint name="right_six_joint" type="revolute">
    <origin xyz="0.0471 0.0036 0" rpy="0 0 0"/>
    <parent link="right_five_link"/>
    <child link="right_six_link"/>
    <axis xyz="0 0 1"/>
    <limit effort="0.7" velocity="23" lower="0" upper="1.84"/>
  <dynamics damping="0.0" friction="0.01"/></joint>
  <link name="right_six_link">
    <inertial>
      <origin xyz="0.02375910756 -0.00135257289 0.00011966865" rpy="0 0 0"/>
      <mass value="0.01385835"/>
      <inertia ixx="0.00000094744556" ixy="0.00000010086310" ixz="0.00000003605469" iyy="0.00000254698095" iyz="0.00000000325710" izz="0.00000204288618"/>
    </inertial>
    <visual>
      <origin xyz="0 0 0" rpy="0 0 0"/>
      <geometry>
        <mesh filename="package://gz_sim/meshes/g1/right_six_link.STL"/>
      </geometry>
      <material name="white">
        <color rgba="0.7 0.7 0.7 1"/>
      </material>
    </visual>
    <collision>
      <origin xyz="0 0 0" rpy="0 0 0"/>
      <geometry>
        <mesh filename="package://gz_sim/meshes/g1/right_six_link.STL"/>
      </geometry>
    </collision>
  </link>

  <gazebo>
    <plugin name="gz::sim::systems::JointStatePublisher" filename="gz-sim-joint-state-publisher-system">
      <update_rate>2000</update_rate>
        <joint_name>left_hip_pitch_joint</joint_name>
        <joint_name>left_hip_roll_joint</joint_name>
        <joint_name>left_hip_yaw_joint</joint_name>
        <joint_name>left_knee_joint</joint_name>
        <joint_name>left_ankle_pitch_joint</joint_name>
        <joint_name>left_ankle_roll_joint</joint_name>
        <joint_name>right_hip_pitch_joint</joint_name>
        <joint_name>right_hip_roll_joint</joint_name>
        <joint_name>right_hip_yaw_joint</joint_name>
        <joint_name>right_knee_joint</joint_name>
        <joint_name>right_ankle_pitch_joint</joint_name>
        <joint_name>right_ankle_roll_joint</joint_name>
        <joint_name>torso_joint</joint_name>
        <joint_name>left_shoulder_pitch_joint</joint_name>
        <joint_name>left_shoulder_roll_joint</joint_name>
        <joint_name>left_shoulder_yaw_joint</joint_name>
        <joint_name>left_elbow_pitch_joint</joint_name>
        <joint_name>left_elbow_roll_joint</joint_name>
        <joint_name>right_shoulder_pitch_joint</joint_name>
        <joint_name>right_shoulder_roll_joint</joint_name>
        <joint_name>right_shoulder_yaw_joint</joint_name>
        <joint_name>right_elbow_pitch_joint</joint_name>
        <joint_name>right_elbow_roll_joint</joint_name>
        <joint_name>left_zero_joint</joint_name>
        <joint_name>left_one_joint</joint_name>
        <joint_name>left_two_joint</joint_name>
        <joint_name>left_three_joint</joint_name>
        <joint_name>left_four_joint</joint_name>
        <joint_name>left_five_joint</joint_name>
        <joint_name>left_six_joint</joint_name>
        <joint_name>right_zero_joint</joint_name>
        <joint_name>right_one_joint</joint_name>
        <joint_name>right_two_joint</joint_name>
        <joint_name>right_three_joint</joint_name>
        <joint_name>right_four_joint</joint_name>
        <joint_name>right_five_joint</joint_name>
        <joint_name>right_six_joint</joint_name>
    </plugin>
  </gazebo>

  <!-- Subscribes to a JointTrajectory message from the /set_joint_trajectory topic
        To publish to this topic type:
            ros2 topic pub -1 /set_joint_trajectory trajectory_msgs/msg/JointTrajectory "{header: {frame_id: base_link}, joint_names: [link1_to_link2, link2_to_link3, etc.], points: [{positions: [0.0,0.0,etc.]}]}"
    -->

  <gazebo>
     <plugin name="gz::sim::systems::JointTrajectoryController" filename="gz-sim-joint-trajectory-controller-system">
        <update_rate>20000</update_rate>
<joint_name>left_hip_pitch_joint</joint_name>
<use_header_start_time>true</use_header_start_time>
<position_p_gain>1200</position_p_gain>
<position_d_gain>0</position_d_gain>
<velocity_p_gain>60</velocity_p_gain>
<velocity_d_gain>0</velocity_d_gain>
<position_cmd_min>-20</position_cmd_min>
<position_cmd_max>20</position_cmd_max>
<velocity_cmd_min>-5</velocity_cmd_min>
<velocity_cmd_max>5</velocity_cmd_max>

<joint_name>left_hip_roll_joint</joint_name>
<use_header_start_time>true</use_header_start_time>
<position_p_gain>1200</position_p_gain>
<position_d_gain>0</position_d_gain>
<velocity_p_gain>60</velocity_p_gain>
<velocity_d_gain>0</velocity_d_gain>
<position_cmd_min>-20</position_cmd_min>
<position_cmd_max>20</position_cmd_max>
<velocity_cmd_min>-5</velocity_cmd_min>
<velocity_cmd_max>5</velocity_cmd_max>

<joint_name>left_hip_yaw_joint</joint_name>
<use_header_start_time>true</use_header_start_time>
<position_p_gain>1200</position_p_gain>
<position_d_gain>0</position_d_gain>
<velocity_p_gain>60</velocity_p_gain>
<velocity_d_gain>0</velocity_d_gain>
<position_cmd_min>-20</position_cmd_min>
<position_cmd_max>20</position_cmd_max>
<velocity_cmd_min>-5</velocity_cmd_min>
<velocity_cmd_max>5</velocity_cmd_max>

<joint_name>left_knee_joint</joint_name>
<use_header_start_time>true</use_header_start_time>
<position_p_gain>1200</position_p_gain>
<position_d_gain>0</position_d_gain>
<velocity_p_gain>60</velocity_p_gain>
<velocity_d_gain>0</velocity_d_gain>
<position_cmd_min>-20</position_cmd_min>
<position_cmd_max>20</position_cmd_max>
<velocity_cmd_min>-5</velocity_cmd_min>
<velocity_cmd_max>5</velocity_cmd_max>

<joint_name>left_ankle_pitch_joint</joint_name>
<use_header_start_time>true</use_header_start_time>
<position_p_gain>1200</position_p_gain>
<position_d_gain>0</position_d_gain>
<velocity_p_gain>60</velocity_p_gain>
<velocity_d_gain>0</velocity_d_gain>
<position_cmd_min>-20</position_cmd_min>
<position_cmd_max>20</position_cmd_max>
<velocity_cmd_min>-5</velocity_cmd_min>
<velocity_cmd_max>5</velocity_cmd_max>

<joint_name>left_ankle_roll_joint</joint_name>
<use_header_start_time>true</use_header_start_time>
<position_p_gain>1200</position_p_gain>
<position_d_gain>0</position_d_gain>
<velocity_p_gain>60</velocity_p_gain>
<velocity_d_gain>0</velocity_d_gain>
<position_cmd_min>-20</position_cmd_min>
<position_cmd_max>20</position_cmd_max>
<velocity_cmd_min>-5</velocity_cmd_min>
<velocity_cmd_max>5</velocity_cmd_max>

<joint_name>right_hip_pitch_joint</joint_name>
<use_header_start_time>true</use_header_start_time>
<position_p_gain>1200</position_p_gain>
<position_d_gain>0</position_d_gain>
<velocity_p_gain>60</velocity_p_gain>
<velocity_d_gain>0</velocity_d_gain>
<position_cmd_min>-20</position_cmd_min>
<position_cmd_max>20</position_cmd_max>
<velocity_cmd_min>-5</velocity_cmd_min>
<velocity_cmd_max>5</velocity_cmd_max>

<joint_name>right_hip_roll_joint</joint_name>
<use_header_start_time>true</use_header_start_time>
<position_p_gain>1200</position_p_gain>
<position_d_gain>0</position_d_gain>
<velocity_p_gain>60</velocity_p_gain>
<velocity_d_gain>0</velocity_d_gain>
<position_cmd_min>-20</position_cmd_min>
<position_cmd_max>20</position_cmd_max>
<velocity_cmd_min>-5</velocity_cmd_min>
<velocity_cmd_max>5</velocity_cmd_max>

<joint_name>right_hip_yaw_joint</joint_name>
<use_header_start_time>true</use_header_start_time>
<position_p_gain>1200</position_p_gain>
<position_d_gain>0</position_d_gain>
<velocity_p_gain>60</velocity_p_gain>
<velocity_d_gain>0</velocity_d_gain>
<position_cmd_min>-20</position_cmd_min>
<position_cmd_max>20</position_cmd_max>
<velocity_cmd_min>-5</velocity_cmd_min>
<velocity_cmd_max>5</velocity_cmd_max>

<joint_name>right_knee_joint</joint_name>
<use_header_start_time>true</use_header_start_time>
<position_p_gain>1200</position_p_gain>
<position_d_gain>0</position_d_gain>
<velocity_p_gain>60</velocity_p_gain>
<velocity_d_gain>0</velocity_d_gain>
<position_cmd_min>-20</position_cmd_min>
<position_cmd_max>20</position_cmd_max>
<velocity_cmd_min>-5</velocity_cmd_min>
<velocity_cmd_max>5</velocity_cmd_max>

<joint_name>right_ankle_pitch_joint</joint_name>
<use_header_start_time>true</use_header_start_time>
<position_p_gain>1200</position_p_gain>
<position_d_gain>0</position_d_gain>
<velocity_p_gain>60</velocity_p_gain>
<velocity_d_gain>0</velocity_d_gain>
<position_cmd_min>-20</position_cmd_min>
<position_cmd_max>20</position_cmd_max>
<velocity_cmd_min>-5</velocity_cmd_min>
<velocity_cmd_max>5</velocity_cmd_max>

<joint_name>right_ankle_roll_joint</joint_name>
<use_header_start_time>true</use_header_start_time>
<position_p_gain>1200</position_p_gain>
<position_d_gain>0</position_d_gain>
<velocity_p_gain>60</velocity_p_gain>
<velocity_d_gain>0</velocity_d_gain>
<position_cmd_min>-20</position_cmd_min>
<position_cmd_max>20</position_cmd_max>
<velocity_cmd_min>-5</velocity_cmd_min>
<velocity_cmd_max>5</velocity_cmd_max>

<joint_name>torso_joint</joint_name>
<use_header_start_time>true</use_header_start_time>
<position_p_gain>100</position_p_gain>
<position_d_gain>0</position_d_gain>
<velocity_p_gain>5</velocity_p_gain>
<velocity_d_gain>0</velocity_d_gain>
<position_cmd_min>-20</position_cmd_min>
<position_cmd_max>20</position_cmd_max>
<velocity_cmd_min>-5</velocity_cmd_min>
<velocity_cmd_max>5</velocity_cmd_max>

<joint_name>left_shoulder_pitch_joint</joint_name>
<use_header_start_time>true</use_header_start_time>
<position_p_gain>100</position_p_gain>
<position_d_gain>0</position_d_gain>
<velocity_p_gain>5</velocity_p_gain>
<velocity_d_gain>0</velocity_d_gain>
<position_cmd_min>-20</position_cmd_min>
<position_cmd_max>20</position_cmd_max>
<velocity_cmd_min>-5</velocity_cmd_min>
<velocity_cmd_max>5</velocity_cmd_max>

<joint_name>left_shoulder_roll_joint</joint_name>
<use_header_start_time>true</use_header_start_time>
<position_p_gain>100</position_p_gain>
<position_d_gain>0</position_d_gain>
<velocity_p_gain>5</velocity_p_gain>
<velocity_d_gain>0</velocity_d_gain>
<position_cmd_min>-20</position_cmd_min>
<position_cmd_max>20</position_cmd_max>
<velocity_cmd_min>-5</velocity_cmd_min>
<velocity_cmd_max>5</velocity_cmd_max>

<joint_name>left_shoulder_yaw_joint</joint_name>
<use_header_start_time>true</use_header_start_time>
<position_p_gain>100</position_p_gain>
<position_d_gain>0</position_d_gain>
<velocity_p_gain>5</velocity_p_gain>
<velocity_d_gain>0</velocity_d_gain>
<position_cmd_min>-20</position_cmd_min>
<position_cmd_max>20</position_cmd_max>
<velocity_cmd_min>-5</velocity_cmd_min>
<velocity_cmd_max>5</velocity_cmd_max>

<joint_name>left_elbow_pitch_joint</joint_name>
<use_header_start_time>true</use_header_start_time>
<position_p_gain>100</position_p_gain>
<position_d_gain>0</position_d_gain>
<velocity_p_gain>5</velocity_p_gain>
<velocity_d_gain>0</velocity_d_gain>
<position_cmd_min>-20</position_cmd_min>
<position_cmd_max>20</position_cmd_max>
<velocity_cmd_min>-5</velocity_cmd_min>
<velocity_cmd_max>5</velocity_cmd_max>

<joint_name>left_elbow_roll_joint</joint_name>
<use_header_start_time>true</use_header_start_time>
<position_p_gain>100</position_p_gain>
<position_d_gain>0</position_d_gain>
<velocity_p_gain>5</velocity_p_gain>
<velocity_d_gain>0</velocity_d_gain>
<position_cmd_min>-20</position_cmd_min>
<position_cmd_max>20</position_cmd_max>
<velocity_cmd_min>-5</velocity_cmd_min>
<velocity_cmd_max>5</velocity_cmd_max>

<joint_name>right_shoulder_pitch_joint</joint_name>
<use_header_start_time>true</use_header_start_time>
<position_p_gain>100</position_p_gain>
<position_d_gain>0</position_d_gain>
<velocity_p_gain>5</velocity_p_gain>
<velocity_d_gain>0</velocity_d_gain>
<position_cmd_min>-20</position_cmd_min>
<position_cmd_max>20</position_cmd_max>
<velocity_cmd_min>-5</velocity_cmd_min>
<velocity_cmd_max>5</velocity_cmd_max>

<joint_name>right_shoulder_roll_joint</joint_name>
<use_header_start_time>true</use_header_start_time>
<position_p_gain>100</position_p_gain>
<position_d_gain>0</position_d_gain>
<velocity_p_gain>5</velocity_p_gain>
<velocity_d_gain>0</velocity_d_gain>
<position_cmd_min>-20</position_cmd_min>
<position_cmd_max>20</position_cmd_max>
<velocity_cmd_min>-5</velocity_cmd_min>
<velocity_cmd_max>5</velocity_cmd_max>

<joint_name>right_shoulder_yaw_joint</joint_name>
<use_header_start_time>true</use_header_start_time>
<position_p_gain>100</position_p_gain>
<position_d_gain>0</position_d_gain>
<velocity_p_gain>5</velocity_p_gain>
<velocity_d_gain>0</velocity_d_gain>
<position_cmd_min>-20</position_cmd_min>
<position_cmd_max>20</position_cmd_max>
<velocity_cmd_min>-5</velocity_cmd_min>
<velocity_cmd_max>5</velocity_cmd_max>

<joint_name>right_elbow_pitch_joint</joint_name>
<use_header_start_time>true</use_header_start_time>
<position_p_gain>100</position_p_gain>
<position_d_gain>0</position_d_gain>
<velocity_p_gain>5</velocity_p_gain>
<velocity_d_gain>0</velocity_d_gain>
<position_cmd_min>-20</position_cmd_min>
<position_cmd_max>20</position_cmd_max>
<velocity_cmd_min>-5</velocity_cmd_min>
<velocity_cmd_max>5</velocity_cmd_max>

<joint_name>right_elbow_roll_joint</joint_name>
<use_header_start_time>true</use_header_start_time>
<position_p_gain>100</position_p_gain>
<position_d_gain>0</position_d_gain>
<velocity_p_gain>5</velocity_p_gain>
<velocity_d_gain>0</velocity_d_gain>
<position_cmd_min>-20</position_cmd_min>
<position_cmd_max>20</position_cmd_max>
<velocity_cmd_min>-5</velocity_cmd_min>
<velocity_cmd_max>5</velocity_cmd_max>

<joint_name>left_zero_joint</joint_name>
<use_header_start_time>true</use_header_start_time>
<position_p_gain>100</position_p_gain>
<position_d_gain>0</position_d_gain>
<velocity_p_gain>5</velocity_p_gain>
<velocity_d_gain>0</velocity_d_gain>
<position_cmd_min>-20</position_cmd_min>
<position_cmd_max>20</position_cmd_max>
<velocity_cmd_min>-5</velocity_cmd_min>
<velocity_cmd_max>5</velocity_cmd_max>

<joint_name>left_one_joint</joint_name>
<use_header_start_time>true</use_header_start_time>
<position_p_gain>100</position_p_gain>
<position_d_gain>0</position_d_gain>
<velocity_p_gain>5</velocity_p_gain>
<velocity_d_gain>0</velocity_d_gain>
<position_cmd_min>-20</position_cmd_min>
<position_cmd_max>20</position_cmd_max>
<velocity_cmd_min>-5</velocity_cmd_min>
<velocity_cmd_max>5</velocity_cmd_max>

<joint_name>left_two_joint</joint_name>
<use_header_start_time>true</use_header_start_time>
<position_p_gain>100</position_p_gain>
<position_d_gain>0</position_d_gain>
<velocity_p_gain>5</velocity_p_gain>
<velocity_d_gain>0</velocity_d_gain>
<position_cmd_min>-20</position_cmd_min>
<position_cmd_max>20</position_cmd_max>
<velocity_cmd_min>-5</velocity_cmd_min>
<velocity_cmd_max>5</velocity_cmd_max>

<joint_name>left_three_joint</joint_name>
<use_header_start_time>true</use_header_start_time>
<position_p_gain>100</position_p_gain>
<position_d_gain>0</position_d_gain>
<velocity_p_gain>5</velocity_p_gain>
<velocity_d_gain>0</velocity_d_gain>
<position_cmd_min>-20</position_cmd_min>
<position_cmd_max>20</position_cmd_max>
<velocity_cmd_min>-5</velocity_cmd_min>
<velocity_cmd_max>5</velocity_cmd_max>

<joint_name>left_four_joint</joint_name>
<use_header_start_time>true</use_header_start_time>
<position_p_gain>100</position_p_gain>
<position_d_gain>0</position_d_gain>
<velocity_p_gain>5</velocity_p_gain>
<velocity_d_gain>0</velocity_d_gain>
<position_cmd_min>-20</position_cmd_min>
<position_cmd_max>20</position_cmd_max>
<velocity_cmd_min>-5</velocity_cmd_min>
<velocity_cmd_max>5</velocity_cmd_max>

<joint_name>left_five_joint</joint_name>
<use_header_start_time>true</use_header_start_time>
<position_p_gain>100</position_p_gain>
<position_d_gain>0</position_d_gain>
<velocity_p_gain>5</velocity_p_gain>
<velocity_d_gain>0</velocity_d_gain>
<position_cmd_min>-20</position_cmd_min>
<position_cmd_max>20</position_cmd_max>
<velocity_cmd_min>-5</velocity_cmd_min>
<velocity_cmd_max>5</velocity_cmd_max>

<joint_name>left_six_joint</joint_name>
<use_header_start_time>true</use_header_start_time>
<position_p_gain>100</position_p_gain>
<position_d_gain>0</position_d_gain>
<velocity_p_gain>5</velocity_p_gain>
<velocity_d_gain>0</velocity_d_gain>
<position_cmd_min>-20</position_cmd_min>
<position_cmd_max>20</position_cmd_max>
<velocity_cmd_min>-5</velocity_cmd_min>
<velocity_cmd_max>5</velocity_cmd_max>

<joint_name>right_zero_joint</joint_name>
<use_header_start_time>true</use_header_start_time>
<position_p_gain>100</position_p_gain>
<position_d_gain>0</position_d_gain>
<velocity_p_gain>5</velocity_p_gain>
<velocity_d_gain>0</velocity_d_gain>
<position_cmd_min>-20</position_cmd_min>
<position_cmd_max>20</position_cmd_max>
<velocity_cmd_min>-5</velocity_cmd_min>
<velocity_cmd_max>5</velocity_cmd_max>

<joint_name>right_one_joint</joint_name>
<use_header_start_time>true</use_header_start_time>
<position_p_gain>100</position_p_gain>
<position_d_gain>0</position_d_gain>
<velocity_p_gain>5</velocity_p_gain>
<velocity_d_gain>0</velocity_d_gain>
<position_cmd_min>-20</position_cmd_min>
<position_cmd_max>20</position_cmd_max>
<velocity_cmd_min>-5</velocity_cmd_min>
<velocity_cmd_max>5</velocity_cmd_max>

<joint_name>right_two_joint</joint_name>
<use_header_start_time>true</use_header_start_time>
<position_p_gain>100</position_p_gain>
<position_d_gain>0</position_d_gain>
<velocity_p_gain>5</velocity_p_gain>
<velocity_d_gain>0</velocity_d_gain>
<position_cmd_min>-20</position_cmd_min>
<position_cmd_max>20</position_cmd_max>
<velocity_cmd_min>-5</velocity_cmd_min>
<velocity_cmd_max>5</velocity_cmd_max>

<joint_name>right_three_joint</joint_name>
<use_header_start_time>true</use_header_start_time>
<position_p_gain>100</position_p_gain>
<position_d_gain>0</position_d_gain>
<velocity_p_gain>5</velocity_p_gain>
<velocity_d_gain>0</velocity_d_gain>
<position_cmd_min>-20</position_cmd_min>
<position_cmd_max>20</position_cmd_max>
<velocity_cmd_min>-5</velocity_cmd_min>
<velocity_cmd_max>5</velocity_cmd_max>

<joint_name>right_four_joint</joint_name>
<use_header_start_time>true</use_header_start_time>
<position_p_gain>100</position_p_gain>
<position_d_gain>0</position_d_gain>
<velocity_p_gain>5</velocity_p_gain>
<velocity_d_gain>0</velocity_d_gain>
<position_cmd_min>-20</position_cmd_min>
<position_cmd_max>20</position_cmd_max>
<velocity_cmd_min>-5</velocity_cmd_min>
<velocity_cmd_max>5</velocity_cmd_max>

<joint_name>right_five_joint</joint_name>
<use_header_start_time>true</use_header_start_time>
<position_p_gain>100</position_p_gain>
<position_d_gain>0</position_d_gain>
<velocity_p_gain>5</velocity_p_gain>
<velocity_d_gain>0</velocity_d_gain>
<position_cmd_min>-20</position_cmd_min>
<position_cmd_max>20</position_cmd_max>
<velocity_cmd_min>-5</velocity_cmd_min>
<velocity_cmd_max>5</velocity_cmd_max>

<joint_name>right_six_joint</joint_name>
<use_header_start_time>true</use_header_start_time>
<position_p_gain>100</position_p_gain>
<position_d_gain>0</position_d_gain>
<velocity_p_gain>5</velocity_p_gain>
<velocity_d_gain>0</velocity_d_gain>
<position_cmd_min>-20</position_cmd_min>
<position_cmd_max>20</position_cmd_max>
<velocity_cmd_min>-5</velocity_cmd_min>
<velocity_cmd_max>5</velocity_cmd_max>
     </plugin>
     <plugin
       filename="gz-sim-pose-publisher-system"
       name="gz::sim::systems::PosePublisher">
       <publish_link_pose>true</publish_link_pose>
       <use_pose_vector_msg>true</use_pose_vector_msg>
     </plugin>
     <plugin
       filename="gz-sim-odometry-publisher-system"
       name="gz::sim::systems::OdometryPublisher">
       <robot_base_frame>h1/pelvis</robot_base_frame>
       <dimensions>3</dimensions>
     </plugin>

  </gazebo>
  <gazebo reference="pelvis">
    <sensor name="imu_sensor" type="imu">
       <always_on>1</always_on>
       <update_rate>1</update_rate>
       <visualize>true</visualize>
       <topic>imu</topic>
       <plugin
        filename="gz-sim-imu-system"
        name="gz::sim::systems::Imu">
        </plugin>
    </sensor>
  </gazebo>

<gazebo reference="right_ankle_roll_joint">
    <sensor name="rarj" type="force_torque">
      <force_torque>
        <frame>sensor</frame>
        <measure_direction>child_to_parent</measure_direction>
        <visualize>true</visualize>
      </force_torque>
      <topic>rarj</topic>
      <plugin
        filename="gz-sim--forcetorque-system"
        name="gz::sim::systems::ForceTorque">
      </plugin>
    </sensor>
  </gazebo>

  <gazebo reference="left_ankle_roll_joint">
    <sensor name="larj" type="force_torque">
      <force_torque>
        <frame>parent</frame>
        <measure_direction>child_to_parent</measure_direction>
      </force_torque>
      <topic>larj</topic>
      <plugin
        filename="gz-sim-forcetorque-system"
        name="gz::sim::systems::ForceTorque">
        </plugin>
    </sensor>
  </gazebo>



  <gazebo reference="right_ankle_roll_link">
    <collision name="collision">
    <surface>
      <friction>
        <ode>
          <mu>100.</mu>
          <mu2>100.</mu2>
        </ode>
      </friction>
    </surface>
    </collision>
  </gazebo>

  <gazebo reference="left_ankle_roll_link">
    <collision name="collision">
    <surface>
      <friction>
        <ode>
          <mu>100.</mu>
          <mu2>100.</mu2>
        </ode>
      </friction>
    </surface>
    </collision>
  </gazebo>

  <gazebo reference="right_ankle_roll_joint">
    <sensor name="rapj" type="force_torque">
      <force_torque>
        <frame>sensor</frame>
        <measure_direction>child_to_parent</measure_direction>
        <visualize>true</visualize>
      </force_torque>
      <topic>g1/right_ankle_force</topic>
      <plugin
        filename="libignition-gazebo-forcetorque-system.so"
        name="ignition::gazebo::systems::ForceTorque">
      </plugin>
    </sensor>
  </gazebo>

  <gazebo reference="left_ankle_roll_joint">
    <sensor name="lapj" type="force_torque">
      <force_torque>
        <frame>parent</frame>
        <measure_direction>child_to_parent</measure_direction>
      </force_torque>
      <topic>g1/left_ankle_force</topic>
      <plugin
        filename="libignition-gazebo-forcetorque-system.so"
        name="ignition::gazebo::systems::ForceTorque">
        </plugin>
    </sensor>
  </gazebo>
</robot>