<?xml version="1.0"?>
<robot name="nemo">

  <!-- Links -->
  <link name="pelvis">
    <inertial>
      <mass value="7.6770570000000005"/>
      <inertia ixx="0.028726694450146615" ixy="0.0" ixz="0.0" iyy="0.028726694450146615" iyz="0.0" izz="0.028726694450146615"/>
    </inertial>

    <!-- Visual Geometry -->
    <visual>
      <geometry>
        <mesh filename="package://gz_sim/meshes/nemo/pelvis_box.stl"/>
      </geometry>
    </visual>

    <!-- Collision Geometry -->
    <collision>
      <geometry>
        <mesh filename="package://gz_sim/meshes/nemo/pelvis_box.stl"/>
      </geometry>
    </collision>

  </link>

  <!-- Joint: floating_base -->
  <!--
  <joint name="floating_base" type="floating">
    <parent link="world"/>
    <child link="pelvis"/>
    <origin xyz="0 0 0.8319" rpy="0 0 0"/>
  </joint>
  -->

  <!-- Link: l_hip_pitch -->
  <link name="l_hip_pitch">
    <inertial>
      <mass value="0.7960545"/>
      <inertia ixx="0.0002677465920866481" ixy="0.0" ixz="0.0" iyy="0.0002677465920866481" iyz="0.0" izz="0.0002677465920866481"/>
    </inertial>

    <!-- Visual Geometry -->
    <visual>
      <geometry>
        <mesh filename="package://gz_sim/meshes/nemo/l_hip_pitch.stl"/>
      </geometry>
    </visual>

    <!-- Collision Geometry -->
    <collision>
      <geometry>
        <mesh filename="package://gz_sim/meshes/nemo/l_hip_pitch.stl"/>
      </geometry>
    </collision>

  </link>

  <!-- Joint: l_hip_pitch -->
  <joint name="l_hip_pitch_joint" type="revolute">
    <parent link="pelvis"/>
    <child link="l_hip_pitch"/>
    <origin xyz="0 0.0762 0" rpy="0 0 0"/>
    <axis xyz="0 1 0"/>
    <limit lower="-3.0" upper="3.0" effort="34.0" velocity="34.0"/>
  </joint>

  <!-- Link: l_hip_roll -->
  <link name="l_hip_roll">
    <inertial>
      <mass value="3.91082805"/>
      <inertia ixx="0.0020885499345463655" ixy="0.0" ixz="0.0" iyy="0.0020885499345463655" iyz="0.0" izz="0.0020885499345463655"/>
    </inertial>

    <!-- Visual Geometry -->
    <visual>
      <geometry>
        <mesh filename="package://gz_sim/meshes/nemo/l_hip_roll.stl"/>
      </geometry>
    </visual>

    <!-- Collision Geometry -->
    <collision>
      <geometry>
        <mesh filename="package://gz_sim/meshes/nemo/l_hip_roll.stl"/>
      </geometry>
    </collision>

  </link>

  <!-- Joint: l_hip_roll -->
  <joint name="l_hip_roll_joint" type="revolute">
    <parent link="l_hip_pitch"/>
    <child link="l_hip_roll"/>
    <origin xyz="-0.05715 0.127 0" rpy="0 0 0"/>
    <axis xyz="1 0 0"/>
    <limit lower="-0.279253" upper="1.0" effort="34.0" velocity="34.0"/>
  </joint>

  <!-- Link: l_hip_yaw -->
  <link name="l_hip_yaw">
    <inertial>
      <mass value="3.0474375"/>
      <inertia ixx="0.005317699121115497" ixy="0.0" ixz="0.0" iyy="0.005317699121115497" iyz="0.0" izz="0.005317699121115497"/>
    </inertial>

    <!-- Visual Geometry -->
    <visual>
      <geometry>
        <mesh filename="package://gz_sim/meshes/nemo/l_hip_yaw.stl"/>
      </geometry>
    </visual>

    <!-- Collision Geometry -->
    <collision>
      <geometry>
        <mesh filename="package://gz_sim/meshes/nemo/l_hip_yaw.stl"/>
      </geometry>
    </collision>

  </link>

  <!-- Joint: l_hip_yaw -->
  <joint name="l_hip_yaw_joint" type="revolute">
    <parent link="l_hip_roll"/>
    <child link="l_hip_yaw"/>
    <origin xyz="0.06254 0 -0.1905" rpy="0 0 0"/>
    <axis xyz="0 0 1"/>
    <limit lower="-2.5" upper="2.5" effort="34.0" velocity="34.0"/>
  </joint>

  <!-- Link: l_knee -->
  <link name="l_knee">
    <inertial>
      <mass value="3.4080436"/>
      <inertia ixx="0.0025045269244811904" ixy="0.0" ixz="0.0" iyy="0.0025045269244811904" iyz="0.0" izz="0.0025045269244811904"/>
    </inertial>

    <!-- Visual Geometry -->
    <visual>
      <geometry>
        <mesh filename="package://gz_sim/meshes/nemo/l_knee.stl"/>
      </geometry>
    </visual>

    <!-- Collision Geometry -->
    <collision>
      <geometry>
        <mesh filename="package://gz_sim/meshes/nemo/l_knee.stl"/>
      </geometry>
    </collision>

  </link>

  <!-- Joint: l_knee -->
  <joint name="l_knee_joint" type="revolute">
    <parent link="l_hip_yaw"/>
    <child link="l_knee"/>
    <origin xyz="0 0 -0.2286" rpy="0 0 0"/>
    <axis xyz="0 1 0"/>
    <limit lower="-0.3" upper="2.0" effort="34.0" velocity="34.0"/>
  </joint>

  <!-- Link: l_foot_pitch -->
  <link name="l_foot_pitch">
    <inertial>
      <mass value="0.8572895"/>
      <inertia ixx="6.937947084078097e-07" ixy="0.0" ixz="0.0" iyy="6.937947084078097e-07" iyz="0.0" izz="6.937947084078097e-07"/>
    </inertial>

    <!-- Visual Geometry -->
    <visual>
      <geometry>
        <mesh filename="package://gz_sim/meshes/nemo/l_foot_pitch.stl"/>
      </geometry>
    </visual>

    <!-- Collision Geometry -->
    <collision>
      <geometry>
        <mesh filename="package://gz_sim/meshes/nemo/l_foot_pitch.stl"/>
      </geometry>
    </collision>

  </link>

  <!-- Joint: l_foot_pitch -->
  <joint name="l_foot_pitch_joint" type="revolute">
    <parent link="l_knee"/>
    <child link="l_foot_pitch"/>
    <origin xyz="0 0.00635 -0.3366" rpy="0 0 0"/>
    <axis xyz="0 1 0"/>
    <limit lower="-0.5" upper="0.5" effort="34.0" velocity="34.0"/>
  </joint>

  <!-- Link: l_foot_roll -->
  <link name="l_foot_roll">
    <inertial>
      <mass value="1.786451"/>
      <inertia ixx="9.93476609435633e-05" ixy="0.0" ixz="0.0" iyy="9.93476609435633e-05" iyz="0.0" izz="9.93476609435633e-05"/>
    </inertial>

    <!-- Visual Geometry -->
    <visual>
      <geometry>
        <mesh filename="package://gz_sim/meshes/nemo/l_foot_roll.stl"/>
      </geometry>
      <!--<material name="metallic"/>-->
    </visual>

    <!-- Collision Geometry -->
    <collision>
      <geometry>
        <mesh filename="package://gz_sim/meshes/nemo/l_foot_roll.stl"/>
      </geometry>
    </collision>

  </link>

  <!-- Joint: l_foot_roll -->
  <joint name="l_foot_roll_joint" type="revolute">
    <parent link="l_foot_pitch"/>
    <child link="l_foot_roll"/>
    <origin xyz="0.0889 0 0" rpy="0 0 0"/>
    <axis xyz="1 0 0"/>
    <limit lower="-1.0" upper="1.0" effort="34.0" velocity="34.0"/>
  </joint>

  <!-- Additional Links and Joints for the Right Leg -->
  <!-- Similar structure for right leg, following the same pattern as the left leg. -->
  <!-- Link: r_hip_pitch -->
  <link name="r_hip_pitch">
    <inertial>
      <mass value="0.7960545"/>
      <inertia ixx="0.0002677465920866481" ixy="0.0" ixz="0.0" iyy="0.0002677465920866481" iyz="0.0" izz="0.0002677465920866481"/>
    </inertial>

    <!-- Visual Geometry -->
    <visual>
      <geometry>
        <mesh filename="package://gz_sim/meshes/nemo/r_hip_pitch.stl"/>
      </geometry>
    </visual>

    <!-- Collision Geometry -->
    <collision>
      <geometry>
        <mesh filename="package://gz_sim/meshes/nemo/r_hip_pitch.stl"/>
      </geometry>
    </collision>

  </link>

  <!-- Joint: r_hip_pitch -->
  <joint name="r_hip_pitch_joint" type="revolute">
    <parent link="pelvis"/>
    <child link="r_hip_pitch"/>
    <origin xyz="0 -0.0762 0" rpy="0 0 0"/>
    <axis xyz="0 1 0"/>
    <limit lower="-3.0" upper="3.0" effort="34.0" velocity="34.0"/>
  </joint>

  <!-- Link: r_hip_roll -->
  <link name="r_hip_roll">
    <inertial>
      <mass value="3.91082805"/>
      <inertia ixx="0.0020885499345463655" ixy="0.0" ixz="0.0" iyy="0.0020885499345463655" iyz="0.0" izz="0.0020885499345463655"/>
    </inertial>

    <!-- Visual Geometry -->
    <visual>
      <geometry>
        <mesh filename="package://gz_sim/meshes/nemo/r_hip_roll.stl"/>
      </geometry>
    </visual>

    <!-- Collision Geometry -->
    <collision>
      <geometry>
        <mesh filename="package://gz_sim/meshes/nemo/r_hip_roll.stl"/>
      </geometry>
    </collision>

  </link>

  <!-- Joint: r_hip_roll -->
  <joint name="r_hip_roll_joint" type="revolute">
    <parent link="r_hip_pitch"/>
    <child link="r_hip_roll"/>
    <origin xyz="-0.05715 -0.127 0" rpy="0 0 0"/>
    <axis xyz="1 0 0"/>
    <limit lower="-1.0" upper="0.279253" effort="34.0" velocity="34.0"/>
  </joint>

  <!-- Link: r_hip_yaw -->
  <link name="r_hip_yaw">
    <inertial>
      <mass value="3.0474375"/>
      <inertia ixx="0.005317699121115497" ixy="0.0" ixz="0.0" iyy="0.005317699121115497" iyz="0.0" izz="0.005317699121115497"/>
    </inertial>

    <!-- Visual Geometry -->
    <visual>
      <geometry>
        <mesh filename="package://gz_sim/meshes/nemo/r_hip_yaw.stl"/>
      </geometry>
    </visual>

    <!-- Collision Geometry -->
    <collision>
      <geometry>
        <mesh filename="package://gz_sim/meshes/nemo/r_hip_yaw.stl"/>
      </geometry>
    </collision>

  </link>

  <!-- Joint: r_hip_yaw -->
  <joint name="r_hip_yaw_joint" type="revolute">
    <parent link="r_hip_roll"/>
    <child link="r_hip_yaw"/>
    <origin xyz="0.06254 0 -0.1905" rpy="0 0 0"/>
    <axis xyz="0 0 1"/>
    <limit lower="-2.5" upper="2.5" effort="34.0" velocity="34.0"/>
  </joint>

  <!-- Link: r_knee -->
  <link name="r_knee">
    <inertial>
      <mass value="3.4080436"/>
      <inertia ixx="0.0025045269244811904" ixy="0.0" ixz="0.0" iyy="0.0025045269244811904" iyz="0.0" izz="0.0025045269244811904"/>
    </inertial>

    <!-- Visual Geometry -->
    <visual>
      <geometry>
        <mesh filename="package://gz_sim/meshes/nemo/r_knee.stl"/>
      </geometry>
    </visual>

    <!-- Collision Geometry -->
    <collision>
      <geometry>
        <mesh filename="package://gz_sim/meshes/nemo/r_knee.stl"/>
      </geometry>
    </collision>

  </link>

  <!-- Joint: r_knee -->
  <joint name="r_knee_joint" type="revolute">
    <parent link="r_hip_yaw"/>
    <child link="r_knee"/>
    <origin xyz="0 0 -0.2286" rpy="0 0 0"/>
    <axis xyz="0 1 0"/>
    <limit lower="-0.3" upper="2.0" effort="34.0" velocity="34.0"/>
  </joint>

  <!-- Link: r_foot_pitch -->
  <link name="r_foot_pitch">
    <inertial>
      <mass value="0.8572895"/>
      <inertia ixx="6.937947084078097e-07" ixy="0.0" ixz="0.0" iyy="6.937947084078097e-07" iyz="0.0" izz="6.937947084078097e-07"/>
    </inertial>

    <!-- Visual Geometry -->
    <visual>
      <geometry>
        <mesh filename="package://gz_sim/meshes/nemo/r_foot_pitch.stl"/>
      </geometry>
    </visual>

    <!-- Collision Geometry -->
    <collision>
      <geometry>
        <mesh filename="package://gz_sim/meshes/nemo/r_foot_pitch.stl"/>
      </geometry>
    </collision>

  </link>

  <!-- Joint: r_foot_pitch -->
  <joint name="r_foot_pitch_joint" type="revolute">
    <parent link="r_knee"/>
    <child link="r_foot_pitch"/>
    <origin xyz="0 -0.00635 -0.3366" rpy="0 0 0"/>
    <axis xyz="0 1 0"/>
    <limit lower="-0.5" upper="0.5" effort="34.0" velocity="34.0"/>
  </joint>

  <!-- Link: r_foot_roll -->
  <link name="r_foot_roll">
    <inertial>
      <mass value="1.786451"/>
      <inertia ixx="9.93476609435633e-05" ixy="0.0" ixz="0.0" iyy="9.93476609435633e-05" iyz="0.0" izz="9.93476609435633e-05"/>
    </inertial>

    <!-- Visual Geometry -->
    <visual>
      <geometry>
        <mesh filename="package://gz_sim/meshes/nemo/r_foot_roll.stl"/>
      </geometry>
    </visual>

    <!-- Collision Geometry -->
    <collision>
      <geometry>
        <mesh filename="package://gz_sim/meshes/nemo/r_foot_roll.stl"/>
      </geometry>
    </collision>

  </link>

  <!-- Joint: r_foot_roll -->
  <joint name="r_foot_roll_joint" type="revolute">
    <parent link="r_foot_pitch"/>
    <child link="r_foot_roll"/>
    <origin xyz="0.0889 0 0" rpy="0 0 0"/>
    <axis xyz="1 0 0"/>
    <limit lower="-1.0" upper="1.0" effort="34.0" velocity="34.0"/>
  </joint>

  <!-- 
  <actuator>
    <position kp="400.0" class="nemo" name="r_hip_pitch" joint="r_hip_pitch" forcerange="-34 34" inheritrange="1"/>
    <position kp="400.0" class="nemo" name="r_hip_roll" joint="r_hip_roll" forcerange="-34 34" inheritrange="1"/>
    <position kp="400.0" class="nemo" name="r_hip_yaw" joint="r_hip_yaw" forcerange="-34 34" inheritrange="1"/>
    <position kp="400.0" class="nemo" name="r_knee" joint="r_knee" forcerange="-34 34" inheritrange="1"/>
    <position kp="400.0" class="nemo" name="r_foot_pitch" joint="r_foot_pitch" forcerange="-34 34" inheritrange="1"/>
    <position kp="400.0" class="nemo" name="r_foot_roll" joint="r_foot_roll" forcerange="-22 22" inheritrange="1"/>

    <position kp="400.0" class="nemo" name="l_hip_pitch" joint="l_hip_pitch" forcerange="-34 34" inheritrange="1"/>
    <position kp="400.0" class="nemo" name="l_hip_roll" joint="l_hip_roll" forcerange="-34 34" inheritrange="1"/>
    <position kp="400.0" class="nemo" name="l_hip_yaw" joint="l_hip_yaw" forcerange="-34 34" inheritrange="1"/>
    <position kp="400.0" class="nemo" name="l_knee" joint="l_knee" forcerange="-34 34" inheritrange="1"/>
    <position kp="400.0" class="nemo" name="l_foot_pitch" joint="l_foot_pitch" forcerange="-34 34" inheritrange="1"/>
    <position kp="400.0" class="nemo" name="l_foot_roll" joint="l_foot_roll" forcerange="-22 22" inheritrange="1"/>
  </actuator>
  -->

  <gazebo>
    <plugin name="gz::sim::systems::JointStatePublisher" filename="gz-sim-joint-state-publisher-system">
      <update_rate>1000</update_rate>
        <joint_name>l_hip_pitch_joint</joint_name>
        <joint_name>l_hip_roll_joint</joint_name>
        <joint_name>l_hip_yaw_joint</joint_name>
        <joint_name>l_knee_joint</joint_name>
        <joint_name>l_foot_pitch_joint</joint_name>
        <joint_name>l_foot_roll_joint</joint_name>
        <joint_name>r_hip_pitch_joint</joint_name>
        <joint_name>r_hip_roll_joint</joint_name>
        <joint_name>r_hip_yaw_joint</joint_name>
        <joint_name>r_knee_joint</joint_name>
        <joint_name>r_foot_pitch_joint</joint_name>
        <joint_name>r_foot_roll_joint</joint_name>
    </plugin>
  </gazebo>

  <gazebo reference="pelvis">
    <sensor name="imu_sensor" type="imu">
       <always_on>1</always_on>
       <update_rate>1</update_rate>
       <visualize>true</visualize>
       <topic>imu</topic>
       <plugin
        filename="gz-sim-imu-system"
        name="gz::sim::systems::Imu">
        </plugin>
    </sensor>
  </gazebo>

  <!-- Keyframe (Stand Position) -->
  <keyframe>
    <key name="stand" qpos="0 0 0.8319 1 0 0 0 0 0 0 0 0 0 0 0 0 0 0 0"/>
  </keyframe>

</robot>