<robot name="nemo3" xmlns:xacro="http://www.ros.org/wiki/xacro">
  <xacro:property name="gz_sim_dir" value="$(find gz_sim)" />
  
  <material name="metallic">
    <color rgba="0.7 0.7 0.7 1" />
  </material>
  <material name="black">
    <color rgba="0.2 0.2 0.2 1" />
  </material>
  <material name="transparent">
    <color rgba="0 0 0 0" />
  </material>

  
  <link name="pelvis">
    <inertial>
      <origin xyz="0.0 0.0 -0.028416610" />
      <mass value="6.17236279" />
      <inertia ixx="0.0004984" iyy="0.0004984" izz="0.0004984" ixy="0.0" iyz="0.0" ixz="0.0" />
    </inertial>
    <visual>
      <geometry>
        <mesh filename="${gz_sim_dir}/meshes/nemo3/pelvis.stl" />
      </geometry>
      <material name="metallic" />
    </visual>
    <collision>
      <geometry>
        <mesh filename="${gz_sim_dir}/meshes/nemo3/pelvis.stl" />
      </geometry>
    </collision>
  </link>

  
  

  
  <joint name="l_hip_pitch_joint" type="revolute">
    <parent link="pelvis" />
    <child link="l_hip_pitch" />
    <origin xyz="0.0 0.074 -0.114" />
    <axis xyz="0 1 0" />
    <limit lower="-3" upper="3" effort="46" velocity="20" />
  </joint>

  <link name="l_hip_pitch">
    <inertial>
      <origin xyz="-0.0265 -0.0195 -0.00001923" />
      <mass value="1.55611213" />
      <inertia ixx="0.00016889" iyy="0.00016889" izz="0.00016889" ixy="0.0" iyz="0.0" ixz="0.0" />
    </inertial>
    <visual>
      <geometry>
        <mesh filename="${gz_sim_dir}/meshes/nemo3/l_hip_pitch.stl" />
      </geometry>
      <material name="metallic" />
    </visual>
    <collision>
      <geometry>
        <mesh filename="${gz_sim_dir}/meshes/nemo3/l_hip_pitch.stl" />
      </geometry>
    </collision>
  </link>

  <joint name="l_hip_roll_joint" type="revolute">
    <parent link="l_hip_pitch" />
    <child link="l_hip_roll" />
    <origin xyz="-0.0655 0.1475 0.0" />
    <axis xyz="1 0 0" />
    <limit lower="-0.279253" upper="1.0472" effort="23" velocity="20" />
  </joint>

  <link name="l_hip_roll">
    <inertial>
      <origin xyz="0.0541 -0.000011 -0.0474" />
      <mass value="1.59270966" />
      <inertia ixx="0.0008254" iyy="0.0008254" izz="0.0008254" ixy="0.0" iyz="0.0" ixz="0.0" />
    </inertial>
    <visual>
      <geometry>
        <mesh filename="${gz_sim_dir}/meshes/nemo3/l_hip_roll.stl" />
      </geometry>
      <material name="metallic" />
    </visual>
    <collision>
      <geometry>
        <mesh filename="${gz_sim_dir}/meshes/nemo3/l_hip_roll.stl" />
      </geometry>
    </collision>
  </link>

 <joint name="l_hip_yaw_joint" type="revolute">
    <parent link="l_hip_roll" />
    <child link="l_hip_yaw" />
    <origin xyz="0.0841 0.0 -0.1158" />
    <axis xyz="0 0 1" />
    <limit lower="-2.5" upper="2.5" effort="23" velocity="20" />
  </joint>
  <link name="l_hip_yaw">
    <inertial>
      <origin xyz="-0.00002282 0.0 -0.06721509" />
      <mass value="1.31136084" />
      <inertia ixx="0.00059246" iyy="0.00059246" izz="0.00059246" ixy="0.0" ixz="0.0" iyz="0.0" />
    </inertial>
    <visual>
      <geometry>
        <mesh filename="${gz_sim_dir}/meshes/nemo3/l_hip_yaw.stl" />
      </geometry>
      <material name="metallic" />
    </visual>
    <collision>
      <geometry>
        <mesh filename="${gz_sim_dir}/meshes/nemo3/l_hip_yaw.stl" />
      </geometry>
    </collision>
  </link>

  <joint name="l_knee_joint" type="revolute">
    <parent link="l_hip_yaw" />
    <child link="l_knee" />
    <origin xyz="0.0 0.0 -0.0855" />
    <axis xyz="0 1 0" />
    <limit lower="-0.3" upper="2" effort="46" velocity="20" />
  </joint>
  <link name="l_knee">
    <inertial>
      <origin xyz="0.0 0.0 -0.103" />
      <mass value="0.280410225" />
      <inertia ixx="0.00029749" iyy="0.00029749" izz="0.00029749" ixy="0.0" ixz="0.0" iyz="0.0" />
    </inertial>
    <visual>
      <geometry>
        <mesh filename="${gz_sim_dir}/meshes/nemo3/l_knee.stl" />
      </geometry>
      <material name="metallic" />
    </visual>
    <collision>
      <geometry>
        <mesh filename="${gz_sim_dir}/meshes/nemo3/l_knee.stl" />
      </geometry>
    </collision>
  </link>

  <joint name="l_foot_pitch_joint" type="revolute">
    <parent link="l_knee" />
    <child link="l_foot_pitch" />
    <origin xyz="0.0 0.0 -0.206" />
    <axis xyz="0 1 0" />
    <limit lower="-0.5" upper="0.5" effort="46" velocity="20" />
  </joint>
  <link name="l_foot_pitch">
    <inertial>
      <origin xyz="0.01828491 0.0 -0.00002282" />
      <mass value="1.31136084" />
      <inertia ixx="0.00004384" iyy="0.00004384" izz="0.00004384" ixy="0.0" ixz="0.0" iyz="0.0" />
    </inertial>
    <visual>
      <geometry>
        <mesh filename="${gz_sim_dir}/meshes/nemo3/l_foot_pitch.stl" />
      </geometry>
      <material name="metallic" />
    </visual>
    <collision>
      <geometry>
        <mesh filename="${gz_sim_dir}/meshes/nemo3/l_foot_pitch.stl" />
      </geometry>
    </collision>
  </link>

  <joint name="l_foot_roll_joint" type="revolute">
    <parent link="l_foot_pitch" />
    <child link="l_foot_roll" />
    <origin xyz="0.0855 0.0 0.0" />
    <axis xyz="1 0 0" />
    <limit lower="-1" upper="1" effort="23" velocity="20" />
  </joint>
  <link name="l_foot_roll">
    <inertial>
      <origin xyz="0.01657002 0.0 -0.03378122" />
      <mass value="1.196944145" />
      <inertia ixx="0.00016946" iyy="0.00016946" izz="0.00016946" ixy="0.0" ixz="0.0" iyz="0.0" />
    </inertial>
    <visual>
      <geometry>
        <mesh filename="${gz_sim_dir}/meshes/nemo3/l_foot_roll.stl" />
      </geometry>
      <material name="metallic" />
    </visual>
    <collision>
      <geometry>
        <mesh filename="${gz_sim_dir}/meshes/nemo3/l_foot_roll.stl" />
      </geometry>
    </collision>
  </link>

  
  <joint name="r_hip_pitch_joint" type="revolute">
    <parent link="pelvis" />
    <child link="r_hip_pitch" />
    <origin xyz="0.0 -0.074 -0.114" />
    <axis xyz="0 1 0" />
    <limit lower="-3" upper="3" effort="46" velocity="20" />
  </joint>

  <link name="r_hip_pitch">
    <inertial>
      <origin xyz="-0.0265 -0.0195 -0.00001923" />
      <mass value="1.55611213" />
      <inertia ixx="0.00016889" iyy="0.00016889" izz="0.00016889" ixy="0.0" iyz="0.0" ixz="0.0" />
    </inertial>
    <visual>
      <geometry>
        <mesh filename="${gz_sim_dir}/meshes/nemo3/l_hip_pitch.stl" />
      </geometry>
      <material name="metallic" />
    </visual>
    <collision>
      <geometry>
        <mesh filename="${gz_sim_dir}/meshes/nemo3/l_hip_pitch.stl" />
      </geometry>
    </collision>
  </link>

  <joint name="r_hip_roll_joint" type="revolute">
    <parent link="r_hip_pitch" />
    <child link="r_hip_roll" />
    <origin xyz="-0.0655 -0.1475 0.0" />
    <axis xyz="1 0 0" />
    <limit lower="-1.0472" upper="0.279253" effort="23" velocity="20" />
  </joint>

  <link name="r_hip_roll">
    <inertial>
      <origin xyz="0.0541 -0.000011 -0.0474" />
      <mass value="1.59270966" />
      <inertia ixx="0.0008254" iyy="0.0008254" izz="0.0008254" ixy="0.0" iyz="0.0" ixz="0.0" />
    </inertial>
    <visual>
      <geometry>
        <mesh filename="${gz_sim_dir}/meshes/nemo3/l_hip_roll.stl" />
      </geometry>
      <material name="metallic" />
    </visual>
    <collision>
      <geometry>
        <mesh filename="${gz_sim_dir}/meshes/nemo3/l_hip_roll.stl" />
      </geometry>
    </collision>
  </link>

  <joint name="r_hip_yaw_joint" type="revolute">
    <parent link="r_hip_roll" />
    <child link="r_hip_yaw" />
    <origin xyz="0.0841 -0.0 -0.1158" />
    <axis xyz="0 0 1" />
    <limit lower="-2.5" upper="2.5" effort="23" velocity="20" />
  </joint>
  <link name="r_hip_yaw">
    <inertial>
      <origin xyz="-0.00002282 0.0 -0.06721509" />
      <mass value="1.31136084" />
      <inertia ixx="0.00059246" iyy="0.00059246" izz="0.00059246" ixy="0.0" ixz="0.0" iyz="0.0" />
    </inertial>
    <visual>
      <geometry>
        <mesh filename="${gz_sim_dir}/meshes/nemo3/l_hip_yaw.stl" />
      </geometry>
      <material name="metallic" />
    </visual>
    <collision>
      <geometry>
        <mesh filename="${gz_sim_dir}/meshes/nemo3/l_hip_yaw.stl" />
      </geometry>
    </collision>
  </link>

  <joint name="r_knee_joint" type="revolute">
    <parent link="r_hip_yaw" />
    <child link="r_knee" />
    <origin xyz="0.0 -0.0 -0.0855" />
    <axis xyz="0 1 0" />
    <limit lower="-0.3" upper="2" effort="46" velocity="20" />
  </joint>
  <link name="r_knee">
    <inertial>
      <origin xyz="0.0 0.0 -0.103" />
      <mass value="0.280410225" />
      <inertia ixx="0.00029749" iyy="0.00029749" izz="0.00029749" ixy="0.0" ixz="0.0" iyz="0.0" />
    </inertial>
    <visual>
      <geometry>
        <mesh filename="${gz_sim_dir}/meshes/nemo3/l_knee.stl" />
      </geometry>
      <material name="metallic" />
    </visual>
    <collision>
      <geometry>
        <mesh filename="${gz_sim_dir}/meshes/nemo3/l_knee.stl" />
      </geometry>
    </collision>
  </link>

  <joint name="r_foot_pitch_joint" type="revolute">
    <parent link="r_knee" />
    <child link="r_foot_pitch" />
    <origin xyz="0.0 -0.0 -0.206" />
    <axis xyz="0 1 0" />
    <limit lower="-0.5" upper="0.5" effort="46" velocity="20" />
  </joint>
  <link name="r_foot_pitch">
    <inertial>
      <origin xyz="0.01828491 0.0 -0.00002282" />
      <mass value="1.31136084" />
      <inertia ixx="0.00004384" iyy="0.00004384" izz="0.00004384" ixy="0.0" ixz="0.0" iyz="0.0" />
    </inertial>
    <visual>
      <geometry>
        <mesh filename="${gz_sim_dir}/meshes/nemo3/l_foot_pitch.stl" />
      </geometry>
      <material name="metallic" />
    </visual>
    <collision>
      <geometry>
        <mesh filename="${gz_sim_dir}/meshes/nemo3/l_foot_pitch.stl" />
      </geometry>
    </collision>
  </link>

  <joint name="r_foot_roll_joint" type="revolute">
    <parent link="r_foot_pitch" />
    <child link="r_foot_roll" />
    <origin xyz="0.0855 -0.0 0.0" />
    <axis xyz="1 0 0" />
    <limit lower="-1" upper="1" effort="23" velocity="20" />
  </joint>
  <link name="r_foot_roll">
    <inertial>
      <origin xyz="0.01657002 0.0 -0.03378122" />
      <mass value="1.196944145" />
      <inertia ixx="0.00016946" iyy="0.00016946" izz="0.00016946" ixy="0.0" ixz="0.0" iyz="0.0" />
    </inertial>
    <visual>
      <geometry>
        <mesh filename="${gz_sim_dir}/meshes/nemo3/l_foot_roll.stl" />
      </geometry>
      <material name="metallic" />
    </visual>
    <collision>
      <geometry>
        <mesh filename="${gz_sim_dir}/meshes/nemo3/l_foot_roll.stl" />
      </geometry>
    </collision>
  </link>

  
  <gazebo>
    <plugin filename="gz_ros2_control-system" name="gz_ros2_control::GazeboSimROS2ControlPlugin">
      <parameters>${gz_sim_dir}/config/nemo3_robot_control.yaml</parameters>
    </plugin>
  </gazebo>

  <ros2_control name="GazeboSystem" type="system">
    <hardware>
      <plugin>gz_ros2_control/GazeboSimSystem</plugin>
    </hardware>
    <joint name="l_hip_pitch_joint">
      <command_interface name="position" />
      <state_interface name="position" />
      <state_interface name="velocity" />
    </joint>
    <joint name="r_hip_pitch_joint">
      <command_interface name="position" />
      <state_interface name="position" />
      <state_interface name="velocity" />
    </joint>
    <joint name="l_hip_roll_joint">
      <command_interface name="position" />
      <state_interface name="position" />
      <state_interface name="velocity" />
    </joint>
    <joint name="r_hip_roll_joint">
      <command_interface name="position" />
      <state_interface name="position" />
      <state_interface name="velocity" />
    </joint>
    <joint name="l_hip_yaw_joint">
      <command_interface name="position" />
      <state_interface name="position" />
      <state_interface name="velocity" />
    </joint>
    <joint name="r_hip_yaw_joint">
      <command_interface name="position" />
      <state_interface name="position" />
      <state_interface name="velocity" />
    </joint>
    <joint name="l_knee_joint">
      <command_interface name="position" />
      <state_interface name="position" />
      <state_interface name="velocity" />
    </joint>
    <joint name="r_knee_joint">
      <command_interface name="position" />
      <state_interface name="position" />
      <state_interface name="velocity" />
    </joint>
    <joint name="l_foot_pitch_joint">
      <command_interface name="position" />
      <state_interface name="position" />
      <state_interface name="velocity" />
    </joint>
    <joint name="r_foot_pitch_joint">
      <command_interface name="position" />
      <state_interface name="position" />
      <state_interface name="velocity" />
    </joint>
    <joint name="l_foot_roll_joint">
      <command_interface name="position" />
      <state_interface name="position" />
      <state_interface name="velocity" />
    </joint>
    <joint name="r_foot_roll_joint">
      <command_interface name="position" />
      <state_interface name="position" />
      <state_interface name="velocity" />
    </joint>
  </ros2_control>

</robot>