<robot name="nemo3" xmlns:xacro="http://www.ros.org/wiki/xacro">
  <xacro:property name="gz_sim_dir" value="$(find gz_sim)" />
  
  <material name="metallic">
    <color rgba="0.7 0.7 0.7 1" />
  </material>
  <material name="black">
    <color rgba="0.2 0.2 0.2 1" />
  </material>
  <material name="transparent">
    <color rgba="0 0 0 0" />
  </material>

  
  <link name="pelvis">
    <inertial>
      <origin xyz="0.0 0.0 -0.028416610" />
      <mass value="6.17236279" />
      <inertia ixx="0.0004984" iyy="0.0004984" izz="0.0004984" ixy="0.0" iyz="0.0" ixz="0.0" />
    </inertial>
    <visual>
      <geometry>
        <mesh filename="${gz_sim_dir}/meshes/nemo3/pelvis.stl" />
      </geometry>
      <material name="metallic" />
    </visual>
    <collision>
      <geometry>
        <mesh filename="${gz_sim_dir}/meshes/nemo3/pelvis.stl" />
      </geometry>
    </collision>
  </link>

  
  

  
  <joint name="l_hip_pitch_joint" type="revolute">
    <parent link="pelvis" />
    <child link="l_hip_pitch" />
    <origin xyz="0.0 0.074 -0.114" />
    <axis xyz="0 1 0" />
    <limit lower="-3" upper="3" effort="46" velocity="20" />
  </joint>

  <link name="l_hip_pitch">
    <inertial>
      <origin xyz="-0.0265 -0.0195 -0.00001923" />
      <mass value="1.55611213" />
      <inertia ixx="0.00016889" iyy="0.00016889" izz="0.00016889" ixy="0.0" iyz="0.0" ixz="0.0" />
    </inertial>
    <visual>
      <geometry>
        <mesh filename="${gz_sim_dir}/meshes/nemo3/l_hip_pitch.stl" />
      </geometry>
      <material name="metallic" />
    </visual>
    <collision>
      <geometry>
        <mesh filename="${gz_sim_dir}/meshes/nemo3/l_hip_pitch.stl" />
      </geometry>
    </collision>
  </link>

  <joint name="l_hip_roll_joint" type="revolute">
    <parent link="l_hip_pitch" />
    <child link="l_hip_roll" />
    <origin xyz="-0.0655 0.1475 0.0" />
    <axis xyz="1 0 0" />
    <limit lower="-0.279253" upper="1.0472" effort="23" velocity="20" />
  </joint>

  <link name="l_hip_roll">
    <inertial>
      <origin xyz="0.0541 -0.000011 -0.0474" />
      <mass value="1.59270966" />
      <inertia ixx="0.0008254" iyy="0.0008254" izz="0.0008254" ixy="0.0" iyz="0.0" ixz="0.0" />
    </inertial>
    <visual>
      <geometry>
        <mesh filename="${gz_sim_dir}/meshes/nemo3/l_hip_roll.stl" />
      </geometry>
      <material name="metallic" />
    </visual>
    <collision>
      <geometry>
        <mesh filename="${gz_sim_dir}/meshes/nemo3/l_hip_roll.stl" />
      </geometry>
    </collision>
  </link>

 <joint name="l_hip_yaw_joint" type="revolute">
    <parent link="l_hip_roll" />
    <child link="l_hip_yaw" />
    <origin xyz="0.0841 0.0 -0.1158" />
    <axis xyz="0 0 1" />
    <limit lower="-2.5" upper="2.5" effort="23" velocity="20" />
  </joint>
  <link name="l_hip_yaw">
    <inertial>
      <origin xyz="-0.00002282 0.0 -0.06721509" />
      <mass value="1.31136084" />
      <inertia ixx="0.00059246" iyy="0.00059246" izz="0.00059246" ixy="0.0" ixz="0.0" iyz="0.0" />
    </inertial>
    <visual>
      <geometry>
        <mesh filename="${gz_sim_dir}/meshes/nemo3/l_hip_yaw.stl" />
      </geometry>
      <material name="metallic" />
    </visual>
    <collision>
      <geometry>
        <mesh filename="${gz_sim_dir}/meshes/nemo3/l_hip_yaw.stl" />
      </geometry>
    </collision>
  </link>

  <joint name="l_knee_joint" type="revolute">
    <parent link="l_hip_yaw" />
    <child link="l_knee" />
    <origin xyz="0.0 0.0 -0.0855" />
    <axis xyz="0 1 0" />
    <limit lower="-0.3" upper="2" effort="46" velocity="20" />
  </joint>
  <link name="l_knee">
    <inertial>
      <origin xyz="0.0 0.0 -0.103" />
      <mass value="0.280410225" />
      <inertia ixx="0.00029749" iyy="0.00029749" izz="0.00029749" ixy="0.0" ixz="0.0" iyz="0.0" />
    </inertial>
    <visual>
      <geometry>
        <mesh filename="${gz_sim_dir}/meshes/nemo3/l_knee.stl" />
      </geometry>
      <material name="metallic" />
    </visual>
    <collision>
      <geometry>
        <mesh filename="${gz_sim_dir}/meshes/nemo3/l_knee.stl" />
      </geometry>
    </collision>
  </link>

  <joint name="l_foot_pitch_joint" type="revolute">
    <parent link="l_knee" />
    <child link="l_foot_pitch" />
    <origin xyz="0.0 0.0 -0.206" />
    <axis xyz="0 1 0" />
    <limit lower="-0.5" upper="0.5" effort="46" velocity="20" />
  </joint>
  <link name="l_foot_pitch">
    <inertial>
      <origin xyz="0.01828491 0.0 -0.00002282" />
      <mass value="1.31136084" />
      <inertia ixx="0.00004384" iyy="0.00004384" izz="0.00004384" ixy="0.0" ixz="0.0" iyz="0.0" />
    </inertial>
    <visual>
      <geometry>
        <mesh filename="${gz_sim_dir}/meshes/nemo3/l_foot_pitch.stl" />
      </geometry>
      <material name="metallic" />
    </visual>
    <collision>
      <geometry>
        <mesh filename="${gz_sim_dir}/meshes/nemo3/l_foot_pitch.stl" />
      </geometry>
    </collision>
  </link>

  <joint name="l_foot_roll_joint" type="revolute">
    <parent link="l_foot_pitch" />
    <child link="l_foot_roll" />
    <origin xyz="0.0855 0.0 0.0" />
    <axis xyz="1 0 0" />
    <limit lower="-1" upper="1" effort="23" velocity="20" />
  </joint>
  <link name="l_foot_roll">
    <inertial>
      <origin xyz="0.01657002 0.0 -0.03378122" />
      <mass value="1.196944145" />
      <inertia ixx="0.00016946" iyy="0.00016946" izz="0.00016946" ixy="0.0" ixz="0.0" iyz="0.0" />
    </inertial>
    <visual>
      <geometry>
        <mesh filename="${gz_sim_dir}/meshes/nemo3/l_foot_roll.stl" />
      </geometry>
      <material name="metallic" />
    </visual>
    <collision>
      <geometry>
        <mesh filename="${gz_sim_dir}/meshes/nemo3/l_foot_roll.stl" />
      </geometry>
    </collision>
  </link>

  
  <joint name="r_hip_pitch_joint" type="revolute">
    <parent link="pelvis" />
    <child link="r_hip_pitch" />
    <origin xyz="0.0 -0.074 -0.114" />
    <axis xyz="0 1 0" />
    <limit lower="-3" upper="3" effort="46" velocity="20" />
  </joint>

  <link name="r_hip_pitch">
    <inertial>
      <origin xyz="-0.0265 -0.0195 -0.00001923" />
      <mass value="1.55611213" />
      <inertia ixx="0.00016889" iyy="0.00016889" izz="0.00016889" ixy="0.0" iyz="0.0" ixz="0.0" />
    </inertial>
    <visual>
      <geometry>
        <mesh filename="${gz_sim_dir}/meshes/nemo3/l_hip_pitch.stl" />
      </geometry>
      <material name="metallic" />
    </visual>
    <collision>
      <geometry>
        <mesh filename="${gz_sim_dir}/meshes/nemo3/l_hip_pitch.stl" />
      </geometry>
    </collision>
  </link>

  <joint name="r_hip_roll_joint" type="revolute">
    <parent link="r_hip_pitch" />
    <child link="r_hip_roll" />
    <origin xyz="-0.0655 -0.1475 0.0" />
    <axis xyz="1 0 0" />
    <limit lower="-1.0472" upper="0.279253" effort="23" velocity="20" />
  </joint>

  <link name="r_hip_roll">
    <inertial>
      <origin xyz="0.0541 -0.000011 -0.0474" />
      <mass value="1.59270966" />
      <inertia ixx="0.0008254" iyy="0.0008254" izz="0.0008254" ixy="0.0" iyz="0.0" ixz="0.0" />
    </inertial>
    <visual>
      <geometry>
        <mesh filename="${gz_sim_dir}/meshes/nemo3/l_hip_roll.stl" />
      </geometry>
      <material name="metallic" />
    </visual>
    <collision>
      <geometry>
        <mesh filename="${gz_sim_dir}/meshes/nemo3/l_hip_roll.stl" />
      </geometry>
    </collision>
  </link>

  <joint name="r_hip_yaw_joint" type="revolute">
    <parent link="r_hip_roll" />
    <child link="r_hip_yaw" />
    <origin xyz="0.0841 -0.0 -0.1158" />
    <axis xyz="0 0 1" />
    <limit lower="-2.5" upper="2.5" effort="23" velocity="20" />
  </joint>
  <link name="r_hip_yaw">
    <inertial>
      <origin xyz="-0.00002282 0.0 -0.06721509" />
      <mass value="1.31136084" />
      <inertia ixx="0.00059246" iyy="0.00059246" izz="0.00059246" ixy="0.0" ixz="0.0" iyz="0.0" />
    </inertial>
    <visual>
      <geometry>
        <mesh filename="${gz_sim_dir}/meshes/nemo3/l_hip_yaw.stl" />
      </geometry>
      <material name="metallic" />
    </visual>
    <collision>
      <geometry>
        <mesh filename="${gz_sim_dir}/meshes/nemo3/l_hip_yaw.stl" />
      </geometry>
    </collision>
  </link>

  <joint name="r_knee_joint" type="revolute">
    <parent link="r_hip_yaw" />
    <child link="r_knee" />
    <origin xyz="0.0 -0.0 -0.0855" />
    <axis xyz="0 1 0" />
    <limit lower="-0.3" upper="2" effort="46" velocity="20" />
  </joint>
  <link name="r_knee">
    <inertial>
      <origin xyz="0.0 0.0 -0.103" />
      <mass value="0.280410225" />
      <inertia ixx="0.00029749" iyy="0.00029749" izz="0.00029749" ixy="0.0" ixz="0.0" iyz="0.0" />
    </inertial>
    <visual>
      <geometry>
        <mesh filename="${gz_sim_dir}/meshes/nemo3/l_knee.stl" />
      </geometry>
      <material name="metallic" />
    </visual>
    <collision>
      <geometry>
        <mesh filename="${gz_sim_dir}/meshes/nemo3/l_knee.stl" />
      </geometry>
    </collision>
  </link>

  <joint name="r_foot_pitch_joint" type="revolute">
    <parent link="r_knee" />
    <child link="r_foot_pitch" />
    <origin xyz="0.0 -0.0 -0.206" />
    <axis xyz="0 1 0" />
    <limit lower="-0.5" upper="0.5" effort="46" velocity="20" />
  </joint>
  <link name="r_foot_pitch">
    <inertial>
      <origin xyz="0.01828491 0.0 -0.00002282" />
      <mass value="1.31136084" />
      <inertia ixx="0.00004384" iyy="0.00004384" izz="0.00004384" ixy="0.0" ixz="0.0" iyz="0.0" />
    </inertial>
    <visual>
      <geometry>
        <mesh filename="${gz_sim_dir}/meshes/nemo3/l_foot_pitch.stl" />
      </geometry>
      <material name="metallic" />
    </visual>
    <collision>
      <geometry>
        <mesh filename="${gz_sim_dir}/meshes/nemo3/l_foot_pitch.stl" />
      </geometry>
    </collision>
  </link>

  <joint name="r_foot_roll_joint" type="revolute">
    <parent link="r_foot_pitch" />
    <child link="r_foot_roll" />
    <origin xyz="0.0855 -0.0 0.0" />
    <axis xyz="1 0 0" />
    <limit lower="-1" upper="1" effort="23" velocity="20" />
  </joint>
  <link name="r_foot_roll">
    <inertial>
      <origin xyz="0.01657002 0.0 -0.03378122" />
      <mass value="1.196944145" />
      <inertia ixx="0.00016946" iyy="0.00016946" izz="0.00016946" ixy="0.0" ixz="0.0" iyz="0.0" />
    </inertial>
    <visual>
      <geometry>
        <mesh filename="${gz_sim_dir}/meshes/nemo3/l_foot_roll.stl" />
      </geometry>
      <material name="metallic" />
    </visual>
    <collision>
      <geometry>
        <mesh filename="${gz_sim_dir}/meshes/nemo3/l_foot_roll.stl" />
      </geometry>
    </collision>
  </link>

  
  <gazebo>
    <plugin filename="gz_ros2_control-system" name="gz_ros2_control::GazeboSimROS2ControlPlugin">
      <parameters>${gz_sim_dir}/config/nemo3_robot_control.yaml</parameters>
    </plugin>
  </gazebo>

  <ros2_control name="GazeboSystem" type="system">
    <hardware>
      <plugin>gz_ros2_control/GazeboSimSystem</plugin>
    </hardware>
    <joint name="l_hip_pitch_joint">
      <command_interface name="position" />
      <state_interface name="position" />
      <state_interface name="velocity" />
    </joint>
    <joint name="r_hip_pitch_joint">
      <command_interface name="position" />
      <state_interface name="position" />
      <state_interface name="velocity" />
    </joint>
    <joint name="l_hip_roll_joint">
      <command_interface name="position" />
      <state_interface name="position" />
      <state_interface name="velocity" />
    </joint>
    <joint name="r_hip_roll_joint">
      <command_interface name="position" />
      <state_interface name="position" />
      <state_interface name="velocity" />
    </j<?xml version="1.0"?>
<robot name="nemo4b" xmlns:xacro="http://ros.org/wiki/xacro">

  <!--
    Top-level link: pelvis
    In MuJoCo, pelvis has a freejoint "floating_base".
    In URDF, we can model that as a floating joint with the "world" (or a fixed base if desired).
    Note: URDF requires inertia in the format:
         ixx, ixy, ixz
              iyy, iyz
                   izz
    And the "origin" for inertial is the COM offset.
  -->

  <!-- =========================
       Pelvis Link
       ========================= -->
  <link name="pelvis">
    <inertial>
      <!-- From MuJoCo: mass="5.11537484" -->
      <!-- fullinertia="0.03 0.03 0.03 0.0 0.0 0.0" means ixx=0.03, iyy=0.03, izz=0.03, cross-terms=0 -->
      <!-- pos="0.0 0.0 0.2" -->
      <origin xyz="0.0 0.0 0.2" rpy="0 0 0"/>
      <mass value="5.11537484"/>
      <inertia
         ixx="0.03"
         ixy="0.0"
         ixz="0.0"
         iyy="0.03"
         iyz="0.0"
         izz="0.03" />
    </inertial>

    <!-- Visual geometry for pelvis (mesh) -->
    <visual>
      <origin xyz="0 0 0" rpy="0 0 0"/>
      <geometry>
        <!-- Adjust the path to where your STL is actually located -->
        <mesh filename="package://nemo4b_description/meshes/pelvis.stl" scale="1 1 1"/>
      </geometry>
      <!-- Optional material -->
      <material name="metallic">
        <color rgba="0.7 0.7 0.7 1"/>
      </material>
    </visual>

    <!-- Collision geometry for pelvis.
         You may use the same mesh, or simplify the collision to boxes/spheres/etc. -->
    <collision>
      <origin xyz="0 0 0" rpy="0 0 0"/>
      <geometry>
        <mesh filename="package://nemo4b_description/meshes/pelvis.stl" scale="1 1 1"/>
      </geometry>
    </collision>
  </link>

  <!--
      The MuJoCo file has a 'freejoint name="floating_base"' for pelvis.
      URDF has no direct "free" joint type; you can approximate it with <joint type="floating"/>.
      If you want it fixed to the world, use <joint type="fixed"/>.
  -->
  <joint name="floating_base" type="floating">
    <!-- This “world” link is implicit. Some people name it "world" or "base_link". -->
    <parent link="world"/>
    <child link="pelvis"/>
    <!-- The MuJoCo 'pos="0.0 0.0 0.6088"' is the initial position. URDF can represent it as: -->
    <origin xyz="0.0 0.0 0.6088" rpy="0 0 0"/>
  </joint>


  <!-- =========================
       Left Hip Pitch
       ========================= -->
  <link name="l_hip_pitch">
    <inertial>
      <!-- MuJoCo says: mass="1.8670971"
           fullinertia="0.00265583 0.00363357 0.00358009 -2e-07 -1.09e-06 -0.0"
           pos="-0.01821923 -0.0 -3.205e-05"
           Interpreted as:
             ixx=0.00265583
             iyy=0.00363357
             izz=0.00358009
             ixy=-2e-07 (very small, usually can be approximated as 0)
             ixz=-1.09e-06
             iyz=0
      -->
      <origin xyz="-0.01821923 0.0 -0.00003205" rpy="0 0 0"/>
      <mass value="1.8670971"/>
      <inertia
        ixx="0.00265583"
        ixy="-0.0000002"
        ixz="-0.00000109"
        iyy="0.00363357"
        iyz="0.0"
        izz="0.00358009" />
    </inertial>

    <visual>
      <origin xyz="0 0 0" rpy="0 0 0"/>
      <geometry>
        <mesh filename="package://nemo4b_description/meshes/l_hip_pitch.stl" scale="1 1 1"/>
      </geometry>
      <material name="metallic">
        <color rgba="0.7 0.7 0.7 1"/>
      </material>
    </visual>

    <!-- For collision, you might use a simpler shape, or the same mesh. -->
    <collision>
      <origin xyz="0 0 0" rpy="0 0 0"/>
      <geometry>
        <mesh filename="package://nemo4b_description/meshes/l_hip_pitch.stl" scale="1 1 1"/>
      </geometry>
    </collision>
  </link>

  <!-- The joint from pelvis to l_hip_pitch -->
  <joint name="l_hip_pitch" type="revolute">
    <parent link="pelvis"/>
    <child link="l_hip_pitch"/>
    <!-- The MuJoCo body "l_hip_pitch" is at pos="0.0 0.0965 -0.112" relative to pelvis -->
    <origin xyz="0.0 0.0965 -0.112" rpy="0 0 0"/>
    <!-- axis="0 1 0" range="-1.3 1.3" -->
    <axis xyz="0 1 0"/>
    <limit lower="-1.3" upper="1.3" effort="47.4" velocity="X.X"/>
  </joint>


  <!-- =========================
       Left Hip Roll
       ========================= -->
  <link name="l_hip_roll">
    <inertial>
      <!-- mass="2.00459959", etc. fullinertia=... -->
      <origin xyz="-0.01740501 0.00001764 -0.05845559" rpy="0 0 0"/>
      <mass value="2.00459959"/>
      <!-- ixx=0.0064706, iyy=0.00633136, izz=0.00303949, cross terms see MuJoCo -->
      <inertia
        ixx="0.0064706"
        ixy="0.00000047"       <!-- derived from the - or + small values in the MuJoCo file -->
        ixz="-0.00070962"
        iyy="0.00633136"
        iyz="0.0000009"
        izz="0.00303949" />
    </inertial>

    <visual>
      <origin xyz="0 0 0" rpy="0 0 0"/>
      <geometry>
        <mesh filename="package://nemo4b_description/meshes/l_hip_roll.stl" scale="1 1 1"/>
      </geometry>
    </visual>

    <collision>
      <origin xyz="0 0 0" rpy="0 0 0"/>
      <geometry>
        <mesh filename="package://nemo4b_description/meshes/l_hip_roll.stl" scale="1 1 1"/>
      </geometry>
    </collision>
  </link>

  <joint name="l_hip_roll" type="revolute">
    <parent link="l_hip_pitch"/>
    <child link="l_hip_roll"/>
    <!-- from MuJoCo pos="-0.07875 0.0 0.0" -->
    <origin xyz="-0.07875 0.0 0.0" rpy="0 0 0"/>
    <axis xyz="1 0 0"/>
    <!-- range="-0.4 1.5", etc. Note the effort limit from the actuatorfrcrange. -->
    <limit lower="-0.4" upper="1.5" effort="23.7" velocity="X.X"/>
  </joint>

  <!-- Repeat for l_hip_yaw, l_knee, l_foot_pitch, l_foot_roll, etc. -->
  <!-- Each one has its own <link> block with <inertial> + <visual> + <collision>, -->
  <!-- and then a <joint> block that connects it to its parent link. -->

  <!-- =========================
       Example foot link & collision box
       ========================= -->
  <link name="l_foot_roll">
    <inertial>
      <!-- from MuJoCo: mass="1.5526793", etc. -->
      <origin xyz="0.00757956 0.00001139 -0.03942379" rpy="0 0 0"/>
      <mass value="1.5526793"/>
      <inertia
         ixx="0.00385478"
         ixy="0.00000054"
         ixz="0.0010808"
         iyy="0.0054167"
         iyz="0.0000003"
         izz="0.00391016" />
    </inertial>

    <visual>
      <origin xyz="0 0 0" rpy="0 0 0"/>
      <geometry>
        <mesh filename="package://nemo4b_description/meshes/l_foot_roll.stl" scale="1 1 1"/>
      </geometry>
    </visual>

    <!-- Collision geometry as a box from the MuJoCo snippet:
         <geom class="collision" name="left_foot" pos="-0.0187 0 -0.07975" size="0.1 0.0505 0.006" type="box"/>
         That implies a box of half-extends=0.1, 0.0505, 0.006 or possibly full side length 0.2 x 0.101 x 0.012.
         In URDF, <box size="X Y Z"/> expects full side lengths, so we must double them if these are half-extents.
         MuJoCo’s “size” is usually half-extent, so the collision box is 0.1 × 0.0505 × 0.006 (full extents). 
         We also shift the box by pos="-0.0187 0 -0.07975"
    -->
    <collision>
      <origin xyz="-0.0187 0 -0.07975" rpy="0 0 0"/>
      <geometry>
        <box size="0.2 0.101 0.012"/>
      </geometry>
    </collision>
  </link>

  <joint name="l_foot_roll" type="revolute">
    <parent link="l_foot_pitch"/>
    <child link="l_foot_roll"/>
    <origin xyz="0.07875 0.0 0.0" rpy="0 0 0"/>
    <axis xyz="1 0 0"/>
    <limit lower="-1.0" upper="1.0" effort="23.7" velocity="X.X"/>
  </joint>

  <!-- =========================
       Right Leg
       =========================
       The same structure as the left leg, but note that some of the meshes are scaled (1 -1 1),
       and joint limits differ slightly (like range="-1.5 0.4" for r_hip_roll).
       You’d replicate the same approach: define r_hip_pitch link/joint, r_hip_roll link/joint, etc.
  -->

  <!-- ... all other right-leg links and joints ... -->


  <!--
      If you want to specify transmissions in ROS2 for each joint, you add <transmission> blocks:
         <transmission name="l_hip_pitch_trans">
           <type>transmission_interface/SimpleTransmission</type>
           <joint name="l_hip_pitch">
             <hardwareInterface>hardware_interface/PositionJointInterface</hardwareInterface>
           </joint>
           <actuator name="motor_l_hip_pitch">
             <mechanicalReduction>1</mechanicalReduction>
           </actuator>
         </transmission>
      etc.
      You’d do that for each joint that is actuated.
  -->

</robot>oint>
    <joint name="l_hip_yaw_joint">
      <command_interface name="position" />
      <state_interface name="position" />
      <state_interface name="velocity" />
    </joint>
    <joint name="r_hip_yaw_joint">
      <command_interface name="position" />
      <state_interface name="position" />
      <state_interface name="velocity" />
    </joint>
    <joint name="l_knee_joint">
      <command_interface name="position" />
      <state_interface name="position" />
      <state_interface name="velocity" />
    </joint>
    <joint name="r_knee_joint">
      <command_interface name="position" />
      <state_interface name="position" />
      <state_interface name="velocity" />
    </joint>
    <joint name="l_foot_pitch_joint">
      <command_interface name="position" />
      <state_interface name="position" />
      <state_interface name="velocity" />
    </joint>
    <joint name="r_foot_pitch_joint">
      <command_interface name="position" />
      <state_interface name="position" />
      <state_interface name="velocity" />
    </joint>
    <joint name="l_foot_roll_joint">
      <command_interface name="position" />
      <state_interface name="position" />
      <state_interface name="velocity" />
    </joint>
    <joint name="r_foot_roll_joint">
      <command_interface name="position" />
      <state_interface name="position" />
      <state_interface name="velocity" />
    </joint>
  </ros2_control>

</robot>