<?xml version="1.0"?>
<sdf version="1.6">
  <model name="nemo">

    <!-- Link: pelvis -->
    <link name="pelvis">
      <inertial>
        <mass>7.6770570000000005</mass>
        <inertia>
          <ixx>0.028726694450146615</ixx>
          <ixy>0.0</ixy>
          <ixz>0.0</ixz>
          <iyy>0.028726694450146615</iyy>
          <iyz>0.0</iyz>
          <izz>0.028726694450146615</izz>
        </inertia>
      </inertial>

      <!-- Visual Geometry -->
      <visual>
        <geometry>
          <mesh filename="assets/pelvis_box.stl"/>
        </geometry>
      </visual>

      <!-- Collision Geometry -->
      <collision>
        <geometry>
          <mesh filename="assets/pelvis_box.stl"/>
        </geometry>
      </collision>

      <!-- IMU Sensor -->
      <sensor name="imu_pelvis" type="imu">
        <pose>0 0 0 0 0 0</pose>
      </sensor>
    </link>

    <!-- Joint: floating_base -->
    <joint name="floating_base" type="free">
      <parent>world</parent>
      <child>pelvis</child>
      <pose>0 0 0.8319 0 0 0</pose>
    </joint>

    <!-- Link: l_hip_pitch -->
    <link name="l_hip_pitch">
      <inertial>
        <mass>0.7960545</mass>
        <inertia>
          <ixx>0.0002677465920866481</ixx>
          <ixy>0.0</ixy>
          <ixz>0.0</ixz>
          <iyy>0.0002677465920866481</iyy>
          <iyz>0.0</iyz>
          <izz>0.0002677465920866481</izz>
        </inertia>
      </inertial>

      <!-- Visual Geometry -->
      <visual>
        <geometry>
          <mesh filename="assets/l_hip_pitch.stl"/>
        </geometry>
      </visual>

      <!-- Collision Geometry -->
      <collision>
        <geometry>
          <mesh filename="assets/l_hip_pitch.stl"/>
        </geometry>
      </collision>

      <!-- IMU Sensor -->
      <sensor name="imu_l_hip_pitch" type="imu">
        <pose>0 0 0 0 0 0</pose>
      </sensor>
    </link>

    <!-- Joint: l_hip_pitch -->
    <joint name="l_hip_pitch" type="revolute">
      <parent>pelvis</parent>
      <child>l_hip_pitch</child>
      <pose>0 0.0762 0 0 0 0</pose>
      <axis>
        <xyz>0 1 0</xyz>
      </axis>
      <limit>
        <lower>-3.0</lower>
        <upper>3.0</upper>
        <effort>34.0</effort>
        <velocity>34.0</velocity>
      </limit>
    </joint>

    <!-- Link: l_hip_roll -->
    <link name="l_hip_roll">
      <inertial>
        <mass>3.91082805</mass>
        <inertia>
          <ixx>0.0020885499345463655</ixx>
          <ixy>0.0</ixy>
          <ixz>0.0</ixz>
          <iyy>0.0020885499345463655</iyy>
          <iyz>0.0</iyz>
          <izz>0.0020885499345463655</izz>
        </inertia>
      </inertial>

      <!-- Visual Geometry -->
      <visual>
        <geometry>
          <mesh filename="assets/l_hip_roll.stl"/>
        </geometry>
      </visual>

      <!-- Collision Geometry -->
      <collision>
        <geometry>
          <mesh filename="assets/l_hip_roll.stl"/>
        </geometry>
      </collision>

      <!-- IMU Sensor -->
      <sensor name="imu_l_hip_roll" type="imu">
        <pose>0 0 0 0 0 0</pose>
      </sensor>
    </link>

    <!-- Joint: l_hip_roll -->
    <joint name="l_hip_roll" type="revolute">
      <parent>l_hip_pitch</parent>
      <child>l_hip_roll</child>
      <pose>-0.05715 0.127 0 0 0 0</pose>
      <axis>
        <xyz>1 0 0</xyz>
      </axis>
      <limit>
        <lower>-0.279253</lower>
        <upper>1.0</upper>
        <effort>34.0</effort>
        <velocity>34.0</velocity>
      </limit>
    </joint>

    <!-- Link: l_hip_yaw -->
    <link name="l_hip_yaw">
      <inertial>
        <mass>3.0474375</mass>
        <inertia>
          <ixx>0.005317699121115497</ixx>
          <ixy>0.0</ixy>
          <ixz>0.0</ixz>
          <iyy>0.005317699121115497</iyy>
          <iyz>0.0</iyz>
          <izz>0.005317699121115497</izz>
        </inertia>
      </inertial>

      <!-- Visual Geometry -->
      <visual>
        <geometry>
          <mesh filename="assets/l_hip_yaw.stl"/>
        </geometry>
      </visual>

      <!-- Collision Geometry -->
      <collision>
        <geometry>
          <mesh filename="assets/l_hip_yaw.stl"/>
        </geometry>
      </collision>

      <!-- IMU Sensor -->
      <sensor name="imu_l_hip_yaw" type="imu">
        <pose>0 0 0 0 0 0</pose>
      </sensor>
    </link>

    <!-- Joint: l_hip_yaw -->
    <joint name="l_hip_yaw" type="revolute">
      <parent>l_hip_roll</parent>
      <child>l_hip_yaw</child>
      <pose>0.06254 0 -0.1905 0 0 0</pose>
      <axis>
        <xyz>0 0 1</xyz>
      </axis>
      <limit>
        <lower>-2.5</lower>
        <upper>2.5</upper>
        <effort>34.0</effort>
        <velocity>34.0</velocity>
      </limit>
    </joint>

    <!-- Continue for other links and joints (l_knee, l_foot_pitch, etc.) -->

  </model>
</sdf>
